Workbook

Sheet May 2
A1: DAILY SALES REPORT
A2: 45414
A3: ITEMS | B3: RETAIL PRICE | C3: PCS SOLD | D3: SALES | E3: DISCOUNTED PRICE | F3: PCS SOLD | G3: SALES | H3: SPECIAL DISC. PRICE | I3: PCS SOLD | J3: SALES | K3: TOTALQTY SOLD | L3: PRODUCTION PRICE | M3: 12% Vat | N3: 10% Mark Up | O3: PROFIT
A4: NAPOLIZ
A5: Backpack Bag | B5: 1750 | D5: =B5*C5 -> 0 | E5: 1600 | G5: =E5*F5 -> 0 | H5: 1400 | J5: =H5*I5 -> 0 | K5: =C5+F5+I5 -> 0 | L5: 840 | M5: 100.8 | N5: 84 | O5: =((B5-L5)*C5)+((E5-L5)*F5)+((H5-L5)*I5) -> 0
A6: Black Tote Bag (Phased Out) | B6: 280 | D6: =B6*C6 -> 0 | G6: =E6*F6 -> 0 | J6: =H6*I6 -> 0 | K6: =C6+F6+I6 -> 0 | L6: 230 | O6: =((B6-L6)*C6)+((E6-L6)*F6)+((H6-L6)*I6) -> 0
A7: Double Canopy | B7: 639 | D7: =B7*C7 -> 0 | E7: 575 | G7: =E7*F7 -> 0 | H7: 500 | J7: =H7*I7 -> 0 | K7: =C7+F7+I7 -> 0 | L7: 330 | M7: 39.6 | N7: 33 | O7: =((B7-L7)*C7)+((E7-L7)*F7)+((H7-L7)*I7) -> 0
A8: Laptop Bag | B8: 1450 | D8: =B8*C8 -> 0 | E8: 1400 | G8: =E8*F8 -> 0 | H8: 1250 | J8: =H8*I8 -> 0 | K8: =C8+F8+I8 -> 0 | L8: 840 | M8: 100.8 | N8: 84 | O8: =((B8-L8)*C8)+((E8-L8)*F8)+((H8-L8)*I8) -> 0
A9: Script Santo Tomas with Tiger Back (B) | B9: 480 | D9: =B9*C9 -> 0 | E9: 460 | G9: =E9*F9 -> 0 | H9: 450 | J9: =H9*I9 -> 0 | K9: =C9+F9+I9 -> 0 | L9: 360 | M9: 43.2 | N9: 36 | O9: =((B9-L9)*C9)+((E9-L9)*F9)+((H9-L9)*I9) -> 0
A10: Side Tiger Hoodie | B10: 1480 | D10: =B10*C10 -> 0 | E10: 1400 | G10: =E10*F10 -> 0 | H10: 1375 | J10: =H10*I10 -> 0 | K10: =C10+F10+I10 -> 0 | L10: 1125 | M10: 135 | N10: 112.5 | O10: =((B10-L10)*C10)+((E10-L10)*F10)+((H10-L10)*I10) -> 0
A11: Sling Bag | B11: 330 | C11: 94 | D11: =B11*C11 -> 31020 | E11: 320 | G11: =E11*F11 -> 0 | H11: 300 | J11: =H11*I11 -> 0 | K11: =C11+F11+I11 -> 94 | L11: 260 | M11: 31.2 | N11: 26 | O11: =((B11-L11)*C11)+((E11-L11)*F11)+((H11-L11)*I11) -> 6580
A12: Front Tiger Hoodie | B12: 1440 | D12: =B12*C12 -> 0 | E12: 1400 | G12: =E12*F12 -> 0 | H12: 1375 | J12: =H12*I12 -> 0 | K12: =C12+F12+I12 -> 0 | L12: 1125 | M12: 135 | N12: 112.5 | O12: =((B12-L12)*C12)+((E12-L12)*F12)+((H12-L12)*I12) -> 0
A13: University of Santo Tomas (B) | B13: 450 | C13: 4 | D13: =B13*C13 -> 1800 | E13: 440 | G13: =E13*F13 -> 0 | H13: 425 | J13: =H13*I13 -> 0 | K13: =C13+F13+I13 -> 4 | L13: 360 | M13: 43.2 | N13: 36 | O13: =((B13-L13)*C13)+((E13-L13)*F13)+((H13-L13)*I13) -> 360
A14: UST Tiger Front and Back Graphic (W) | B14: 500 | D14: =B14*C14 -> 0 | E14: 480 | G14: =E14*F14 -> 0 | H14: 450 | J14: =H14*I14 -> 0 | K14: =C14+F14+I14 -> 0 | L14: 360 | M14: 43.2 | N14: 36 | O14: =((B14-L14)*C14)+((E14-L14)*F14)+((H14-L14)*I14) -> 0
A15: White Tote Bag | B15: 260 | C15: 181 | D15: =B15*C15 -> 47060 | E15: 250 | G15: =E15*F15 -> 0 | H15: 240 | J15: =H15*I15 -> 0 | K15: =C15+F15+I15 -> 181 | L15: 200 | M15: 24 | N15: 20 | O15: =((B15-L15)*C15)+((E15-L15)*F15)+((H15-L15)*I15) -> 10860
A16: Wind Breaker | B16: 1650 | C16: 2 | D16: =B16*C16 -> 3300 | E16: 1600 | G16: =E16*F16 -> 0 | H16: 1500 | J16: =H16*I16 -> 0 | K16: =C16+F16+I16 -> 2 | L16: 1125 | M16: 135 | N16: 112.5 | O16: =((B16-L16)*C16)+((E16-L16)*F16)+((H16-L16)*I16) -> 1050
C17: TOTAL | D17: =SUM(D5:D16) -> 83180 | F17: TOTAL | G17: =SUM(G5:G16) -> 0 | I17: TOTAL | J17: =SUM(J5:J16) -> 0 | L17: TOTAL | O17: =SUM(O5:O16) -> 18850
A18: JYL | B18: RETAIL PRICE | C18: PCS SOLD | D18: SALES | E18: DISCOUNTED PRICE | F18: PCS SOLD | G18: SALES | H18: SPECIAL DISC. PRICE | I18: PCS SOLD | J18: SALES | K18: TOTALQTY SOLD | L18: PRODUCTION PRICE | O18: PROFIT
A19: GT Shirt | B19: 375 | D19: =B19*C19 -> 0 | E19: 350 | G19: =E19*F19 -> 0 | H19: 325 | J19: =H19*I19 -> 0 | K19: =C19+F19+I19 -> 0 | L19: 250 | M19: 30 | N19: 25 | O19: =((B19-L19)*C19)+((E19-L19)*F19)+((H19-L19)*I19) -> 0
A20: Jacket | B20: 1900 | C20: 3 | D20: =B20*C20 -> 5700 | E20: 1700 | G20: =E20*F20 -> 0 | H20: 1500 | J20: =H20*I20 -> 0 | K20: =C20+F20+I20 -> 3 | L20: 1200 | M20: 144 | N20: 120 | O20: =((B20-L20)*C20)+((E20-L20)*F20)+((H20-L20)*I20) -> 2100
A21: Poloshirt 123456 | B21: 860 | C21: 5 | D21: =B21*C21 -> 4300 | E21: 800 | G21: =E21*F21 -> 0 | H21: 750 | J21: =H21*I21 -> 0 | K21: =C21+F21+I21 -> 5 | L21: 600 | M21: 72 | N21: 60 | O21: =((B21-L21)*C21)+((E21-L21)*F21)+((H21-L21)*I21) -> 1300
A22: VB Jersey w/ sig. (Phased Out) | B22: 2800 | D22: =B22*C22 -> 0 | G22: =E22*F22 -> 0 | J22: =H22*I22 -> 0 | K22: =C22+F22+I22 -> 0 | L22: 800 | M22: 96 | N22: 80 | O22: =((B22-L22)*C22)+((E22-L22)*F22)+((H22-L22)*I22) -> 0
A23: VB Jersey w/o sig. | B23: 2000 | D23: =B23*C23 -> 0 | E23: 1800 | G23: =E23*F23 -> 0 | H23: 1500 | J23: =H23*I23 -> 0 | K23: =C23+F23+I23 -> 0 | L23: 800 | O23: =((B23-L23)*C23)+((E23-L23)*F23)+((H23-L23)*I23) -> 0
A24: VB Jersey w/o sig. | B24: 1500 | C24: 3 | D24: =B24*C24 -> 4500 | E24: 1400 | G24: =E24*F24 -> 0 | H24: 1300 | J24: =H24*I24 -> 0 | K24: =C24+F24+I24 -> 3 | L24: 800 | O24: =((B24-L24)*C24)+((E24-L24)*F24)+((H24-L24)*I24) -> 2100
A25: VB Jersey w/o sig. | B25: 1000 | D25: =B25*C25 -> 0 | E25: 980 | G25: =E25*F25 -> 0 | H25: 950 | J25: =H25*I25 -> 0 | K25: =C25+F25+I25 -> 0 | L25: 800 | O25: =((B25-L25)*C25)+((E25-L25)*F25)+((H25-L25)*I25) -> 0
A26: VB Jersey with sig. (Phased Out) | B26: 1500 | D26: =B26*C26 -> 0 | G26: =E26*F26 -> 0 | J26: =H26*I26 -> 0 | K26: =C26+F26+I26 -> 0 | L26: 800 | O26: =((B26-L26)*C26)+((E26-L26)*F26)+((H26-L26)*I26) -> 0
C27: TOTAL | D27: =SUM(D19:D26) -> 14500 | F27: TOTAL | G27: =SUM(G19:G26) -> 0 | I27: TOTAL | J27: =SUM(J19:J26) -> 0 | L27: TOTAL | O27: =SUM(O19:O26) -> 5500
A28: JUC | B28: RETAIL PRICE | C28: PCS SOLD | D28: SALES | E28: DISCOUNTED PRICE | F28: PCS SOLD | G28: SALES | H28: SPECIAL DISC. PRICE | I28: PCS SOLD | J28: SALES | K28: TOTALQTY SOLD | L28: PRODUCTION PRICE | O28: PROFIT
A29: UST OAT Hoodie Jacket | B29: 1450 | C29: 1 | D29: =B29*C29 -> 1450 | E29: 1400 | G29: =E29*F29 -> 0 | H29: 1300 | J29: =H29*I29 -> 0 | K29: =C29+F29+I29 -> 1 | L29: 1000 | M29: 120 | N29: 100 | O29: =((B29-L29)*C29)+((E29-L29)*F29)+((H29-L29)*I29) -> 450
A30: UST OAT T-Shirt | B30: 375 | D30: =B30*C30 -> 0 | E30: 360 | G30: =E30*F30 -> 0 | H30: 340 | J30: =H30*I30 -> 0 | K30: =C30+F30+I30 -> 0 | L30: 280 | M30: 33.6 | N30: 28 | O30: =((B30-L30)*C30)+((E30-L30)*F30)+((H30-L30)*I30) -> 0
A31: UST T-Shirt Sports | B31: 430 | C31: 9 | D31: =B31*C31 -> 3870 | E31: 400 | G31: =E31*F31 -> 0 | H31: 350 | J31: =H31*I31 -> 0 | K31: =C31+F31+I31 -> 9 | L31: 260 | M31: 31.2 | N31: 26 | O31: =((B31-L31)*C31)+((E31-L31)*F31)+((H31-L31)*I31) -> 1530
A32: UST T-Shirt Tiger Pattern | B32: 450 | C32: 2 | D32: =B32*C32 -> 900 | E32: 430 | G32: =E32*F32 -> 0 | H32: 400 | J32: =H32*I32 -> 0 | K32: =C32+F32+I32 -> 2 | L32: 330 | M32: 39.6 | N32: 33 | O32: =((B32-L32)*C32)+((E32-L32)*F32)+((H32-L32)*I32) -> 240
A33: UST Happy Tiger | B33: 450 | D33: =B33*C33 -> 0 | E33: 400 | G33: =E33*F33 -> 0 | H33: 375 | J33: =H33*I33 -> 0 | K33: =C33+F33+I33 -> 0 | L33: 280 | M33: 33.6 | N33: 28 | O33: =((B33-L33)*C33)+((E33-L33)*F33)+((H33-L33)*I33) -> 0
A34: OAT Tote Bag (Phased Out) | B34: 220 | D34: =B34*C34 -> 0 | G34: =E34*F34 -> 0 | J34: =H34*I34 -> 0 | K34: =C34+F34+I34 -> 0 | L34: 120 | O34: =((B34-L34)*C34)+((E34-L34)*F34)+((H34-L34)*I34) -> 0
C35: TOTAL | D35: =SUM(D31:D34) -> 4770 | F35: TOTAL | G35: =SUM(G31:G34) -> 0 | I35: TOTAL | J35: =SUM(J31:J34) -> 0 | L35: TOTAL | O35: =SUM(O29:O34) -> 2220
A36: USTORE | B36: RETAIL PRICE | C36: PCS SOLD | D36: SALES | E36: DISCOUNTED PRICE | F36: PCS SOLD | G36: SALES | H36: SPECIAL DISC. PRICE | I36: PCS SOLD | J36: SALES | K36: TOTALQTY SOLD | L36: PRODUCTION PRICE | O36: PROFIT
A37: Auto Umbrella | B37: 250 | D37: =B37*C37 -> 0 | G37: =E37*F37 -> 0 | J37: =H37*I37 -> 0 | K37: =C37+F37+I37 -> 0 | O37: =((B37-L37)*C37)+((E37-L37)*F37)+((H37-L37)*I37) -> 0
A38: Bag | B38: 250 | D38: =B38*C38 -> 0 | G38: =E38*F38 -> 0 | J38: =H38*I38 -> 0 | K38: =C38+F38+I38 -> 0 | O38: =((B38-L38)*C38)+((E38-L38)*F38)+((H38-L38)*I38) -> 0
A39: Eco Bag CGEEE! | B39: 50 | C39: 3 | D39: =B39*C39 -> 150 | E39: 35 | G39: =E39*F39 -> 0 | J39: =H39*I39 -> 0 | K39: =C39+F39+I39 -> 3 | O39: =((B39-L39)*C39)+((E39-L39)*F39)+((H39-L39)*I39) -> 150
A40: Keychain | B40: 150 | C40: 2 | D40: =B40*C40 -> 300 | E40: 120 | G40: =E40*F40 -> 0 | H40: 75 | J40: =H40*I40 -> 0 | K40: =C40+F40+I40 -> 2 | O40: =((B40-L40)*C40)+((E40-L40)*F40)+((H40-L40)*I40) -> 300
...

Sheet May 3
A1: DAILY SALES REPORT
A2: 45415
A3: ITEMS | B3: RETAIL PRICE | C3: PCS SOLD | D3: SALES | E3: DISCOUNTED PRICE | F3: PCS SOLD | G3: SALES | H3: SPECIAL DISC. PRICE | I3: PCS SOLD | J3: SALES | K3: TOTAL SALES | L3: TOTALQTY SOLD | M3: PRODUCTION PRICE | N3: 12% Vat | O3: 10% Mark Up | P3: PROFIT
A4: NAPOLIZ
A5: Backpack Bag | B5: 1750 | D5: =B5*C5 -> 0 | E5: 1600 | G5: =E5*F5 -> 0 | H5: 1400 | J5: =H5*I5 -> 0 | K5: =D5+G5+J5 -> 0 | L5: =C5+F5+I5 -> 0 | M5: 840 | N5: 100.8 | O5: 84 | P5: =((B5-M5)*C5)+((E5-M5)*F5)+((H5-M5)*I5) -> 0
A6: Black Tote Bag (Phased Out) | B6: 280 | D6: =B6*C6 -> 0 | G6: =E6*F6 -> 0 | J6: =H6*I6 -> 0 | K6: =D6+G6+J6 -> 0 | L6: =C6+F6+I6 -> 0 | M6: 230 | P6: =((B6-M6)*C6)+((E6-M6)*F6)+((H6-M6)*I6) -> 0
A7: Double Canopy | B7: 639 | D7: =B7*C7 -> 0 | E7: 575 | G7: =E7*F7 -> 0 | H7: 500 | J7: =H7*I7 -> 0 | K7: =D7+G7+J7 -> 0 | L7: =C7+F7+I7 -> 0 | M7: 330 | N7: 39.6 | O7: 33 | P7: =((B7-M7)*C7)+((E7-M7)*F7)+((H7-M7)*I7) -> 0
A8: Laptop Bag | B8: 1450 | D8: =B8*C8 -> 0 | E8: 1400 | G8: =E8*F8 -> 0 | H8: 1250 | J8: =H8*I8 -> 0 | K8: =D8+G8+J8 -> 0 | L8: =C8+F8+I8 -> 0 | M8: 840 | N8: 100.8 | O8: 84 | P8: =((B8-M8)*C8)+((E8-M8)*F8)+((H8-M8)*I8) -> 0
A9: Script Santo Tomas with Tiger Back (B) | B9: 480 | D9: =B9*C9 -> 0 | E9: 460 | G9: =E9*F9 -> 0 | H9: 450 | J9: =H9*I9 -> 0 | K9: =D9+G9+J9 -> 0 | L9: =C9+F9+I9 -> 0 | M9: 360 | N9: 43.2 | O9: 36 | P9: =((B9-M9)*C9)+((E9-M9)*F9)+((H9-M9)*I9) -> 0
A10: Side Tiger Hoodie | B10: 1480 | C10: 1 | D10: =B10*C10 -> 1480 | E10: 1400 | G10: =E10*F10 -> 0 | H10: 1375 | J10: =H10*I10 -> 0 | K10: =D10+G10+J10 -> 1480 | L10: =C10+F10+I10 -> 1 | M10: 1125 | N10: 135 | O10: 112.5 | P10: =((B10-M10)*C10)+((E10-M10)*F10)+((H10-M10)*I10) -> 355
A11: Sling Bag | B11: 330 | D11: =B11*C11 -> 0 | E11: 320 | G11: =E11*F11 -> 0 | H11: 300 | J11: =H11*I11 -> 0 | K11: =D11+G11+J11 -> 0 | L11: =C11+F11+I11 -> 0 | M11: 260 | N11: 31.2 | O11: 26 | P11: =((B11-M11)*C11)+((E11-M11)*F11)+((H11-M11)*I11) -> 0
A12: Front Tiger Hoodie | B12: 1440 | D12: =B12*C12 -> 0 | E12: 1400 | G12: =E12*F12 -> 0 | H12: 1375 | J12: =H12*I12 -> 0 | K12: =D12+G12+J12 -> 0 | L12: =C12+F12+I12 -> 0 | M12: 1125 | N12: 135 | O12: 112.5 | P12: =((B12-M12)*C12)+((E12-M12)*F12)+((H12-M12)*I12) -> 0
A13: University of Santo Tomas (B) | B13: 450 | C13: 7 | D13: =B13*C13 -> 3150 | E13: 440 | G13: =E13*F13 -> 0 | H13: 425 | I13: 8 | J13: =H13*I13 -> 3400 | K13: =D13+G13+J13 -> 6550 | L13: =C13+F13+I13 -> 15 | M13: 360 | N13: 43.2 | O13: 36 | P13: =((B13-M13)*C13)+((E13-M13)*F13)+((H13-M13)*I13) -> 1150
A14: UST Tiger Front and Back Graphic (W) | B14: 500 | C14: 2 | D14: =B14*C14 -> 1000 | E14: 480 | G14: =E14*F14 -> 0 | H14: 450 | J14: =H14*I14 -> 0 | K14: =D14+G14+J14 -> 1000 | L14: =C14+F14+I14 -> 2 | M14: 360 | N14: 43.2 | O14: 36 | P14: =((B14-M14)*C14)+((E14-M14)*F14)+((H14-M14)*I14) -> 280
A15: White Tote Bag | B15: 260 | C15: 3 | D15: =B15*C15 -> 780 | E15: 250 | G15: =E15*F15 -> 0 | H15: 240 | J15: =H15*I15 -> 0 | K15: =D15+G15+J15 -> 780 | L15: =C15+F15+I15 -> 3 | M15: 200 | N15: 24 | O15: 20 | P15: =((B15-M15)*C15)+((E15-M15)*F15)+((H15-M15)*I15) -> 180
A16: Wind Breaker | B16: 1650 | D16: =B16*C16 -> 0 | E16: 1600 | G16: =E16*F16 -> 0 | H16: 1500 | I16: 3 | J16: =H16*I16 -> 4500 | K16: =D16+G16+J16 -> 4500 | L16: =C16+F16+I16 -> 3 | M16: 1125 | N16: 135 | O16: 112.5 | P16: =((B16-M16)*C16)+((E16-M16)*F16)+((H16-M16)*I16) -> 1125
C17: TOTAL | D17: =SUM(D5:D16) -> 6410 | F17: TOTAL | G17: =SUM(G5:G16) -> 0 | I17: TOTAL | J17: =SUM(J5:J16) -> 7900 | K17: =D17+G17+J17 -> 14310 | M17: TOTAL | P17: =SUM(P5:P16) -> 3090
A18: JYL | B18: RETAIL PRICE | C18: PCS SOLD | D18: SALES | E18: DISCOUNTED PRICE | F18: PCS SOLD | G18: SALES | H18: SPECIAL DISC. PRICE | I18: PCS SOLD | J18: SALES | K18: TOTAL SALES | L18: TOTALQTY SOLD | M18: PRODUCTION PRICE | N18: 12% Vat | O18: 10% Mark Up | P18: PROFIT
A19: GT Shirt | B19: 375 | D19: =B19*C19 -> 0 | E19: 350 | G19: =E19*F19 -> 0 | H19: 325 | J19: =H19*I19 -> 0 | K19: =D19+G19+J19 -> 0 | L19: =C19+F19+I19 -> 0 | M19: 250 | N19: 30 | O19: 25 | P19: =((B19-M19)*C19)+((E19-M19)*F19)+((H19-M19)*I19) -> 0
A20: Jacket | B20: 1900 | D20: =B20*C20 -> 0 | E20: 1700 | G20: =E20*F20 -> 0 | H20: 1500 | J20: =H20*I20 -> 0 | K20: =D20+G20+J20 -> 0 | L20: =C20+F20+I20 -> 0 | M20: 1200 | N20: 144 | O20: 120 | P20: =((B20-M20)*C20)+((E20-M20)*F20)+((H20-M20)*I20) -> 0
A21: Poloshirt 123456 | B21: 860 | C21: 1 | D21: =B21*C21 -> 860 | E21: 800 | G21: =E21*F21 -> 0 | H21: 750 | J21: =H21*I21 -> 0 | K21: =D21+G21+J21 -> 860 | L21: =C21+F21+I21 -> 1 | M21: 600 | N21: 72 | O21: 60 | P21: =((B21-M21)*C21)+((E21-M21)*F21)+((H21-M21)*I21) -> 260
A22: VB Jersey w/ sig. (Phased Out) | B22: 2800 | D22: =B22*C22 -> 0 | G22: =E22*F22 -> 0 | J22: =H22*I22 -> 0 | K22: =D22+G22+J22 -> 0 | L22: =C22+F22+I22 -> 0 | M22: 800 | N22: 96 | O22: 80 | P22: =((B22-M22)*C22)+((E22-M22)*F22)+((H22-M22)*I22) -> 0
A23: VB Jersey w/o sig. | B23: 2000 | D23: =B23*C23 -> 0 | E23: 1800 | G23: =E23*F23 -> 0 | H23: 1500 | J23: =H23*I23 -> 0 | K23: =D23+G23+J23 -> 0 | L23: =C23+F23+I23 -> 0 | M23: 800 | P23: =((B23-M23)*C23)+((E23-M23)*F23)+((H23-M23)*I23) -> 0
A24: VB Jersey w/o sig. | B24: 1500 | D24: =B24*C24 -> 0 | E24: 1400 | G24: =E24*F24 -> 0 | H24: 1300 | J24: =H24*I24 -> 0 | K24: =D24+G24+J24 -> 0 | L24: =C24+F24+I24 -> 0 | M24: 800 | P24: =((B24-M24)*C24)+((E24-M24)*F24)+((H24-M24)*I24) -> 0
A25: VB Jersey w/o sig. | B25: 1000 | D25: =B25*C25 -> 0 | E25: 980 | G25: =E25*F25 -> 0 | H25: 950 | J25: =H25*I25 -> 0 | K25: =D25+G25+J25 -> 0 | L25: =C25+F25+I25 -> 0 | M25: 800 | P25: =((B25-M25)*C25)+((E25-M25)*F25)+((H25-M25)*I25) -> 0
A26: VB Jersey with sig. (Phased Out) | B26: 1500 | D26: =B26*C26 -> 0 | G26: =E26*F26 -> 0 | J26: =H26*I26 -> 0 | K26: =D26+G26+J26 -> 0 | L26: =C26+F26+I26 -> 0 | M26: 800 | P26: =((B26-M26)*C26)+((E26-M26)*F26)+((H26-M26)*I26) -> 0
C27: TOTAL | D27: =SUM(D19:D26) -> 860 | F27: TOTAL | G27: =SUM(G19:G26) -> 0 | I27: TOTAL | J27: =SUM(J19:J26) -> 0 | K27: =D27+G27+J27 -> 860 | M27: TOTAL | P27: =SUM(P19:P26) -> 260
A28: JUC | B28: RETAIL PRICE | C28: PCS SOLD | D28: SALES | E28: DISCOUNTED PRICE | F28: PCS SOLD | G28: SALES | H28: SPECIAL DISC. PRICE | I28: PCS SOLD | J28: SALES | K28: TOTAL SALES | L28: TOTALQTY SOLD | M28: PRODUCTION PRICE | N28: 12% Vat | O28: 10% Mark Up | P28: PROFIT
A29: UST OAT Hoodie Jacket | B29: 1450 | D29: =B29*C29 -> 0 | E29: 1400 | G29: =E29*F29 -> 0 | H29: 1300 | J29: =H29*I29 -> 0 | K29: =D29+G29+J29 -> 0 | L29: =C29+F29+I29 -> 0 | M29: 1000 | N29: 120 | O29: 100 | P29: =((B29-M29)*C29)+((E29-M29)*F29)+((H29-M29)*I29) -> 0
A30: UST OAT MUG | B30: 150 | D30: =B30*C30 -> 0 | E30: 140 | G30: =E30*F30 -> 0 | H30: 135 | J30: =H30*I30 -> 0 | K30: =D30+G30+J30 -> 0 | L30: =C30+F30+I30 -> 0 | M30: 100 | N30: 12 | O30: 10 | P30: =((B30-M30)*C30)+((E30-M30)*F30)+((H30-M30)*I30) -> 0
A31: UST OAT T-Shirt | B31: 375 | D31: =B31*C31 -> 0 | E31: 360 | G31: =E31*F31 -> 0 | H31: 340 | J31: =H31*I31 -> 0 | K31: =D31+G31+J31 -> 0 | L31: =C31+F31+I31 -> 0 | M31: 280 | N31: 33.6 | O31: 28 | P31: =((B31-M31)*C31)+((E31-M31)*F31)+((H31-M31)*I31) -> 0
A32: UST T-Shirt Sports | B32: 430 | C32: 10 | D32: =B32*C32 -> 4300 | E32: 400 | G32: =E32*F32 -> 0 | H32: 350 | J32: =H32*I32 -> 0 | K32: =D32+G32+J32 -> 4300 | L32: =C32+F32+I32 -> 10 | M32: 260 | N32: 31.2 | O32: 26 | P32: =((B32-M32)*C32)+((E32-M32)*F32)+((H32-M32)*I32) -> 1700
A33: UST T-Shirt Tiger Pattern | B33: 450 | D33: =B33*C33 -> 0 | E33: 430 | G33: =E33*F33 -> 0 | H33: 400 | J33: =H33*I33 -> 0 | K33: =D33+G33+J33 -> 0 | L33: =C33+F33+I33 -> 0 | M33: 330 | N33: 39.6 | O33: 33 | P33: =((B33-M33)*C33)+((E33-M33)*F33)+((H33-M33)*I33) -> 0
A34: UST Happy Tiger | B34: 450 | D34: =B34*C34 -> 0 | E34: 400 | G34: =E34*F34 -> 0 | H34: 375 | J34: =H34*I34 -> 0 | K34: =D34+G34+J34 -> 0 | L34: =C34+F34+I34 -> 0 | M34: 280 | N34: 33.6 | O34: 28 | P34: =((B34-M34)*C34)+((E34-M34)*F34)+((H34-M34)*I34) -> 0
A35: OAT Tote Bag (Phased Out) | B35: 220 | D35: =B35*C35 -> 0 | G35: =E35*F35 -> 0 | J35: =H35*I35 -> 0 | K35: =D35+G35+J35 -> 0 | L35: =C35+F35+I35 -> 0 | M35: 120 | P35: =((B35-M35)*C35)+((E35-M35)*F35)+((H35-M35)*I35) -> 0
C36: TOTAL | D36: =SUM(D29:D35) -> 4300 | F36: TOTAL | G36: =SUM(G29:G35) -> 0 | I36: TOTAL | J36: =SUM(J29:J35) -> 0 | K36: =D36+G36+J36 -> 4300 | M36: TOTAL | P36: =SUM(P29:P35) -> 1700
A37: USTORE | B37: RETAIL PRICE | C37: PCS SOLD | D37: SALES | E37: DISCOUNTED PRICE | F37: PCS SOLD | G37: SALES | H37: SPECIAL DISC. PRICE | I37: PCS SOLD | J37: SALES | K37: TOTAL SALES | L37: TOTALQTY SOLD | M37: PRODUCTION PRICE | N37: 12% Vat | O37: 10% Mark Up | P37: PROFIT
A38: Auto Umbrella | B38: 250 | D38: =B38*C38 -> 0 | G38: =E38*F38 -> 0 | J38: =H38*I38 -> 0 | K38: =D38+G38+J38 -> 0 | L38: =C38+F38+I38 -> 0 | P38: =((B38-M38)*C38)+((E38-M38)*F38)+((H38-M38)*I38) -> 0
A39: Bag | B39: 250 | D39: =B39*C39 -> 0 | G39: =E39*F39 -> 0 | J39: =H39*I39 -> 0 | K39: =D39+G39+J39 -> 0 | L39: =C39+F39+I39 -> 0 | P39: =((B39-M39)*C39)+((E39-M39)*F39)+((H39-M39)*I39) -> 0
A40: Eco Bag CGEEE! | B40: 50 | D40: =B40*C40 -> 0 | E40: 35 | G40: =E40*F40 -> 0 | J40: =H40*I40 -> 0 | K40: =D40+G40+J40 -> 0 | L40: =C40+F40+I40 -> 0 | P40: =((B40-M40)*C40)+((E40-M40)*F40)+((H40-M40)*I40) -> 0
...

Sheet May 4
A1: DAILY SALES REPORT
A2: 45415
A3: ITEMS | B3: RETAIL PRICE | C3: PCS SOLD | D3: SALES | E3: DISCOUNTED PRICE | F3: PCS SOLD | G3: SALES | H3: SPECIAL DISC. PRICE | I3: PCS SOLD | J3: SALES | K3: TOTAL SALES | L3: TOTALQTY SOLD | M3: PRODUCTION PRICE | N3: 12% Vat | O3: 10% Mark Up | P3: PROFIT
A4: NAPOLIZ
A5: Backpack Bag | B5: 1750 | D5: =B5*C5 -> 0 | E5: 1600 | G5: =E5*F5 -> 0 | H5: 1400 | J5: =H5*I5 -> 0 | K5: =D5+G5+J5 -> 0 | L5: =C5+F5+I5 -> 0 | M5: 840 | N5: 100.8 | O5: 84 | P5: =((B5-M5)*C5)+((E5-M5)*F5)+((H5-M5)*I5) -> 0
A6: Black Tote Bag (Phased Out) | B6: 280 | D6: =B6*C6 -> 0 | G6: =E6*F6 -> 0 | J6: =H6*I6 -> 0 | K6: =D6+G6+J6 -> 0 | L6: =C6+F6+I6 -> 0 | M6: 230 | P6: =((B6-M6)*C6)+((E6-M6)*F6)+((H6-M6)*I6) -> 0
A7: Double Canopy | B7: 639 | D7: =B7*C7 -> 0 | E7: 575 | G7: =E7*F7 -> 0 | H7: 500 | J7: =H7*I7 -> 0 | K7: =D7+G7+J7 -> 0 | L7: =C7+F7+I7 -> 0 | M7: 330 | N7: 39.6 | O7: 33 | P7: =((B7-M7)*C7)+((E7-M7)*F7)+((H7-M7)*I7) -> 0
A8: Laptop Bag | B8: 1450 | D8: =B8*C8 -> 0 | E8: 1400 | G8: =E8*F8 -> 0 | H8: 1250 | J8: =H8*I8 -> 0 | K8: =D8+G8+J8 -> 0 | L8: =C8+F8+I8 -> 0 | M8: 840 | N8: 100.8 | O8: 84 | P8: =((B8-M8)*C8)+((E8-M8)*F8)+((H8-M8)*I8) -> 0
A9: Script Santo Tomas with Tiger Back (B) | B9: 480 | C9: 4 | D9: =B9*C9 -> 1920 | E9: 460 | G9: =E9*F9 -> 0 | H9: 450 | J9: =H9*I9 -> 0 | K9: =D9+G9+J9 -> 1920 | L9: =C9+F9+I9 -> 4 | M9: 360 | N9: 43.2 | O9: 36 | P9: =((B9-M9)*C9)+((E9-M9)*F9)+((H9-M9)*I9) -> 480
A10: Side Tiger Hoodie | B10: 1480 | D10: =B10*C10 -> 0 | E10: 1400 | G10: =E10*F10 -> 0 | H10: 1375 | J10: =H10*I10 -> 0 | K10: =D10+G10+J10 -> 0 | L10: =C10+F10+I10 -> 0 | M10: 1125 | N10: 135 | O10: 112.5 | P10: =((B10-M10)*C10)+((E10-M10)*F10)+((H10-M10)*I10) -> 0
A11: Sling Bag | B11: 330 | D11: =B11*C11 -> 0 | E11: 320 | G11: =E11*F11 -> 0 | H11: 300 | J11: =H11*I11 -> 0 | K11: =D11+G11+J11 -> 0 | L11: =C11+F11+I11 -> 0 | M11: 260 | N11: 31.2 | O11: 26 | P11: =((B11-M11)*C11)+((E11-M11)*F11)+((H11-M11)*I11) -> 0
A12: Front Tiger Hoodie | B12: 1440 | C12: 1 | D12: =B12*C12 -> 1440 | E12: 1400 | G12: =E12*F12 -> 0 | H12: 1375 | J12: =H12*I12 -> 0 | K12: =D12+G12+J12 -> 1440 | L12: =C12+F12+I12 -> 1 | M12: 1125 | N12: 135 | O12: 112.5 | P12: =((B12-M12)*C12)+((E12-M12)*F12)+((H12-M12)*I12) -> 315
A13: University of Santo Tomas (B) | B13: 450 | D13: =B13*C13 -> 0 | E13: 440 | G13: =E13*F13 -> 0 | H13: 425 | J13: =H13*I13 -> 0 | K13: =D13+G13+J13 -> 0 | L13: =C13+F13+I13 -> 0 | M13: 360 | N13: 43.2 | O13: 36 | P13: =((B13-M13)*C13)+((E13-M13)*F13)+((H13-M13)*I13) -> 0
A14: UST Tiger Front and Back Graphic (W) | B14: 500 | C14: 1 | D14: =B14*C14 -> 500 | E14: 480 | G14: =E14*F14 -> 0 | H14: 450 | J14: =H14*I14 -> 0 | K14: =D14+G14+J14 -> 500 | L14: =C14+F14+I14 -> 1 | M14: 360 | N14: 43.2 | O14: 36 | P14: =((B14-M14)*C14)+((E14-M14)*F14)+((H14-M14)*I14) -> 140
A15: White Tote Bag | B15: 260 | D15: =B15*C15 -> 0 | E15: 250 | G15: =E15*F15 -> 0 | H15: 240 | J15: =H15*I15 -> 0 | K15: =D15+G15+J15 -> 0 | L15: =C15+F15+I15 -> 0 | M15: 200 | N15: 24 | O15: 20 | P15: =((B15-M15)*C15)+((E15-M15)*F15)+((H15-M15)*I15) -> 0
A16: Wind Breaker | B16: 1650 | C16: 1 | D16: =B16*C16 -> 1650 | E16: 1600 | G16: =E16*F16 -> 0 | H16: 1500 | J16: =H16*I16 -> 0 | K16: =D16+G16+J16 -> 1650 | L16: =C16+F16+I16 -> 1 | M16: 1125 | N16: 135 | O16: 112.5 | P16: =((B16-M16)*C16)+((E16-M16)*F16)+((H16-M16)*I16) -> 525
C17: TOTAL | D17: =SUM(D5:D16) -> 5510 | F17: TOTAL | G17: =SUM(G5:G16) -> 0 | I17: TOTAL | J17: =SUM(J5:J16) -> 0 | K17: =D17+G17+J17 -> 5510 | M17: TOTAL | P17: =SUM(P5:P16) -> 1460
A18: JYL | B18: RETAIL PRICE | C18: PCS SOLD | D18: SALES | E18: DISCOUNTED PRICE | F18: PCS SOLD | G18: SALES | H18: SPECIAL DISC. PRICE | I18: PCS SOLD | J18: SALES | K18: TOTAL SALES | L18: TOTALQTY SOLD | M18: PRODUCTION PRICE | N18: 12% Vat | O18: 10% Mark Up | P18: PROFIT
A19: GT Shirt | B19: 375 | D19: =B19*C19 -> 0 | E19: 350 | G19: =E19*F19 -> 0 | H19: 325 | J19: =H19*I19 -> 0 | K19: =D19+G19+J19 -> 0 | L19: =C19+F19+I19 -> 0 | M19: 250 | N19: 30 | O19: 25 | P19: =((B19-M19)*C19)+((E19-M19)*F19)+((H19-M19)*I19) -> 0
A20: Jacket | B20: 1900 | D20: =B20*C20 -> 0 | E20: 1700 | G20: =E20*F20 -> 0 | H20: 1500 | J20: =H20*I20 -> 0 | K20: =D20+G20+J20 -> 0 | L20: =C20+F20+I20 -> 0 | M20: 1200 | N20: 144 | O20: 120 | P20: =((B20-M20)*C20)+((E20-M20)*F20)+((H20-M20)*I20) -> 0
A21: Poloshirt 123456 | B21: 860 | D21: =B21*C21 -> 0 | E21: 800 | G21: =E21*F21 -> 0 | H21: 750 | J21: =H21*I21 -> 0 | K21: =D21+G21+J21 -> 0 | L21: =C21+F21+I21 -> 0 | M21: 600 | N21: 72 | O21: 60 | P21: =((B21-M21)*C21)+((E21-M21)*F21)+((H21-M21)*I21) -> 0
A22: VB Jersey w/ sig. (Phased Out) | B22: 2800 | D22: =B22*C22 -> 0 | G22: =E22*F22 -> 0 | J22: =H22*I22 -> 0 | K22: =D22+G22+J22 -> 0 | L22: =C22+F22+I22 -> 0 | M22: 800 | N22: 96 | O22: 80 | P22: =((B22-M22)*C22)+((E22-M22)*F22)+((H22-M22)*I22) -> 0
A23: VB Jersey w/o sig. | B23: 2000 | D23: =B23*C23 -> 0 | E23: 1800 | G23: =E23*F23 -> 0 | H23: 1500 | J23: =H23*I23 -> 0 | K23: =D23+G23+J23 -> 0 | L23: =C23+F23+I23 -> 0 | M23: 800 | P23: =((B23-M23)*C23)+((E23-M23)*F23)+((H23-M23)*I23) -> 0
A24: VB Jersey w/o sig. | B24: 1500 | D24: =B24*C24 -> 0 | E24: 1400 | G24: =E24*F24 -> 0 | H24: 1300 | J24: =H24*I24 -> 0 | K24: =D24+G24+J24 -> 0 | L24: =C24+F24+I24 -> 0 | M24: 800 | P24: =((B24-M24)*C24)+((E24-M24)*F24)+((H24-M24)*I24) -> 0
A25: VB Jersey w/o sig. | B25: 1000 | D25: =B25*C25 -> 0 | E25: 980 | G25: =E25*F25 -> 0 | H25: 950 | J25: =H25*I25 -> 0 | K25: =D25+G25+J25 -> 0 | L25: =C25+F25+I25 -> 0 | M25: 800 | P25: =((B25-M25)*C25)+((E25-M25)*F25)+((H25-M25)*I25) -> 0
A26: VB Jersey with sig. (Phased Out) | B26: 1500 | D26: =B26*C26 -> 0 | G26: =E26*F26 -> 0 | J26: =H26*I26 -> 0 | K26: =D26+G26+J26 -> 0 | L26: =C26+F26+I26 -> 0 | M26: 800 | P26: =((B26-M26)*C26)+((E26-M26)*F26)+((H26-M26)*I26) -> 0
C27: TOTAL | D27: =SUM(D19:D26) -> 0 | F27: TOTAL | G27: =SUM(G19:G26) -> 0 | I27: TOTAL | J27: =SUM(J19:J26) -> 0 | K27: =D27+G27+J27 -> 0 | M27: TOTAL | P27: =SUM(P19:P26) -> 0
A28: JUC | B28: RETAIL PRICE | C28: PCS SOLD | D28: SALES | E28: DISCOUNTED PRICE | F28: PCS SOLD | G28: SALES | H28: SPECIAL DISC. PRICE | I28: PCS SOLD | J28: SALES | K28: TOTAL SALES | L28: TOTALQTY SOLD | M28: PRODUCTION PRICE | N28: 12% Vat | O28: 10% Mark Up | P28: PROFIT
A29: UST OAT Hoodie Jacket | B29: 1450 | C29: 2 | D29: =B29*C29 -> 2900 | E29: 1400 | G29: =E29*F29 -> 0 | H29: 1300 | J29: =H29*I29 -> 0 | K29: =D29+G29+J29 -> 2900 | L29: =C29+F29+I29 -> 2 | M29: 1000 | N29: 120 | O29: 100 | P29: =((B29-M29)*C29)+((E29-M29)*F29)+((H29-M29)*I29) -> 900
A30: UST OAT MUG | B30: 150 | D30: =B30*C30 -> 0 | E30: 140 | G30: =E30*F30 -> 0 | H30: 135 | J30: =H30*I30 -> 0 | K30: =D30+G30+J30 -> 0 | L30: =C30+F30+I30 -> 0 | M30: 110 | N30: 12 | O30: 10 | P30: =((B30-M30)*C30)+((E30-M30)*F30)+((H30-M30)*I30) -> 0
A31: UST OAT MUG (WE) Inside | B31: 150 | D31: =B31*C31 -> 0 | E31: 140 | G31: =E31*F31 -> 0 | H31: 135 | J31: =H31*I31 -> 0 | K31: =D31+G31+J31 -> 0 | L31: =C31+F31+I31 -> 0 | M31: 100 | N31: 12 | O31: 10 | P31: =((B31-M31)*C31)+((E31-M31)*F31)+((H31-M31)*I31) -> 0
A32: UST OAT T-Shirt | B32: 375 | D32: =B32*C32 -> 0 | E32: 360 | G32: =E32*F32 -> 0 | H32: 340 | J32: =H32*I32 -> 0 | K32: =D32+G32+J32 -> 0 | L32: =C32+F32+I32 -> 0 | M32: 280 | N32: 33.6 | O32: 28 | P32: =((B32-M32)*C32)+((E32-M32)*F32)+((H32-M32)*I32) -> 0
A33: UST T-Shirt Sports | B33: 430 | C33: 3 | D33: =B33*C33 -> 1290 | E33: 400 | G33: =E33*F33 -> 0 | H33: 350 | J33: =H33*I33 -> 0 | K33: =D33+G33+J33 -> 1290 | L33: =C33+F33+I33 -> 3 | M33: 260 | N33: 31.2 | O33: 26 | P33: =((B33-M33)*C33)+((E33-M33)*F33)+((H33-M33)*I33) -> 510
A34: UST T-Shirt Tiger Pattern | B34: 450 | C34: 1 | D34: =B34*C34 -> 450 | E34: 430 | G34: =E34*F34 -> 0 | H34: 400 | J34: =H34*I34 -> 0 | K34: =D34+G34+J34 -> 450 | L34: =C34+F34+I34 -> 1 | M34: 330 | N34: 39.6 | O34: 33 | P34: =((B34-M34)*C34)+((E34-M34)*F34)+((H34-M34)*I34) -> 120
A35: UST Happy Tiger | B35: 450 | C35: 4 | D35: =B35*C35 -> 1800 | E35: 400 | F35: 2 | G35: =E35*F35 -> 800 | H35: 375 | J35: =H35*I35 -> 0 | K35: =D35+G35+J35 -> 2600 | L35: =C35+F35+I35 -> 6 | M35: 280 | N35: 33.6 | O35: 28 | P35: =((B35-M35)*C35)+((E35-M35)*F35)+((H35-M35)*I35) -> 920
A36: OAT Tote Bag (Phased Out) | B36: 220 | D36: =B36*C36 -> 0 | G36: =E36*F36 -> 0 | J36: =H36*I36 -> 0 | K36: =D36+G36+J36 -> 0 | L36: =C36+F36+I36 -> 0 | M36: 120 | P36: =((B36-M36)*C36)+((E36-M36)*F36)+((H36-M36)*I36) -> 0
C37: TOTAL | D37: =SUM(D29:D36) -> 6440 | F37: TOTAL | G37: =SUM(G29:G36) -> 800 | I37: TOTAL | J37: =SUM(J29:J36) -> 0 | K37: =D37+G37+J37 -> 7240 | M37: TOTAL | P37: =SUM(P29:P36) -> 2450
A38: USTORE | B38: RETAIL PRICE | C38: PCS SOLD | D38: SALES | E38: DISCOUNTED PRICE | F38: PCS SOLD | G38: SALES | H38: SPECIAL DISC. PRICE | I38: PCS SOLD | J38: SALES | K38: TOTAL SALES | L38: TOTALQTY SOLD | M38: PRODUCTION PRICE | N38: 12% Vat | O38: 10% Mark Up | P38: PROFIT
A39: Auto Umbrella | B39: 250 | D39: =B39*C39 -> 0 | G39: =E39*F39 -> 0 | J39: =H39*I39 -> 0 | K39: =D39+G39+J39 -> 0 | L39: =C39+F39+I39 -> 0 | P39: =((B39-M39)*C39)+((E39-M39)*F39)+((H39-M39)*I39) -> 0
A40: Bag | B40: 250 | D40: =B40*C40 -> 0 | G40: =E40*F40 -> 0 | J40: =H40*I40 -> 0 | K40: =D40+G40+J40 -> 0 | L40: =C40+F40+I40 -> 0 | P40: =((B40-M40)*C40)+((E40-M40)*F40)+((H40-M40)*I40) -> 0
...

Sheet May 6
A1: DAILY SALES REPORT
A2: 45415
A3: ITEMS | B3: RETAIL PRICE | C3: PCS SOLD | D3: SALES | E3: DISCOUNTED PRICE | F3: PCS SOLD | G3: SALES | H3: SPECIAL DISC. PRICE | I3: PCS SOLD | J3: SALES | K3: TOTAL SALES | L3: TOTALQTY SOLD | M3: PRODUCTION PRICE | N3: 12% Vat | O3: 10% Mark Up | P3: PROFIT
A4: NAPOLIZ
A5: Backpack Bag | B5: 1750 | D5: =B5*C5 -> 0 | E5: 1600 | G5: =E5*F5 -> 0 | H5: 1400 | J5: =H5*I5 -> 0 | K5: =D5+G5+J5 -> 0 | L5: =C5+F5+I5 -> 0 | M5: 840 | N5: 100.8 | O5: 84 | P5: =((B5-M5)*C5)+((E5-M5)*F5)+((H5-M5)*I5) -> 0
A6: Black Tote Bag (Phased Out) | B6: 280 | D6: =B6*C6 -> 0 | G6: =E6*F6 -> 0 | J6: =H6*I6 -> 0 | K6: =D6+G6+J6 -> 0 | L6: =C6+F6+I6 -> 0 | M6: 230 | P6: =((B6-M6)*C6)+((E6-M6)*F6)+((H6-M6)*I6) -> 0
A7: Double Canopy | B7: 639 | D7: =B7*C7 -> 0 | E7: 575 | G7: =E7*F7 -> 0 | H7: 500 | J7: =H7*I7 -> 0 | K7: =D7+G7+J7 -> 0 | L7: =C7+F7+I7 -> 0 | M7: 330 | N7: 39.6 | O7: 33 | P7: =((B7-M7)*C7)+((E7-M7)*F7)+((H7-M7)*I7) -> 0
A8: Laptop Bag | B8: 1450 | D8: =B8*C8 -> 0 | E8: 1400 | G8: =E8*F8 -> 0 | H8: 1250 | J8: =H8*I8 -> 0 | K8: =D8+G8+J8 -> 0 | L8: =C8+F8+I8 -> 0 | M8: 840 | N8: 100.8 | O8: 84 | P8: =((B8-M8)*C8)+((E8-M8)*F8)+((H8-M8)*I8) -> 0
A9: Script Santo Tomas with Tiger Back (B) | B9: 480 | D9: =B9*C9 -> 0 | E9: 460 | G9: =E9*F9 -> 0 | H9: 450 | J9: =H9*I9 -> 0 | K9: =D9+G9+J9 -> 0 | L9: =C9+F9+I9 -> 0 | M9: 360 | N9: 43.2 | O9: 36 | P9: =((B9-M9)*C9)+((E9-M9)*F9)+((H9-M9)*I9) -> 0
A10: Side Tiger Hoodie | B10: 1480 | C10: 1 | D10: =B10*C10 -> 1480 | E10: 1400 | G10: =E10*F10 -> 0 | H10: 1375 | J10: =H10*I10 -> 0 | K10: =D10+G10+J10 -> 1480 | L10: =C10+F10+I10 -> 1 | M10: 1125 | N10: 135 | O10: 112.5 | P10: =((B10-M10)*C10)+((E10-M10)*F10)+((H10-M10)*I10) -> 355
A11: Sling Bag | B11: 330 | D11: =B11*C11 -> 0 | E11: 320 | G11: =E11*F11 -> 0 | H11: 300 | J11: =H11*I11 -> 0 | K11: =D11+G11+J11 -> 0 | L11: =C11+F11+I11 -> 0 | M11: 260 | N11: 31.2 | O11: 26 | P11: =((B11-M11)*C11)+((E11-M11)*F11)+((H11-M11)*I11) -> 0
A12: Front Tiger Hoodie | B12: 1440 | C12: 1 | D12: =B12*C12 -> 1440 | E12: 1400 | G12: =E12*F12 -> 0 | H12: 1375 | J12: =H12*I12 -> 0 | K12: =D12+G12+J12 -> 1440 | L12: =C12+F12+I12 -> 1 | M12: 1125 | N12: 135 | O12: 112.5 | P12: =((B12-M12)*C12)+((E12-M12)*F12)+((H12-M12)*I12) -> 315
A13: University of Santo Tomas (B) | B13: 450 | C13: 1 | D13: =B13*C13 -> 450 | E13: 440 | G13: =E13*F13 -> 0 | H13: 425 | J13: =H13*I13 -> 0 | K13: =D13+G13+J13 -> 450 | L13: =C13+F13+I13 -> 1 | M13: 360 | N13: 43.2 | O13: 36 | P13: =((B13-M13)*C13)+((E13-M13)*F13)+((H13-M13)*I13) -> 90
A14: UST Tiger Front and Back Graphic (W) | B14: 500 | D14: =B14*C14 -> 0 | E14: 480 | G14: =E14*F14 -> 0 | H14: 450 | J14: =H14*I14 -> 0 | K14: =D14+G14+J14 -> 0 | L14: =C14+F14+I14 -> 0 | M14: 360 | N14: 43.2 | O14: 36 | P14: =((B14-M14)*C14)+((E14-M14)*F14)+((H14-M14)*I14) -> 0
A15: White Tote Bag | B15: 260 | C15: 2 | D15: =B15*C15 -> 520 | E15: 250 | G15: =E15*F15 -> 0 | H15: 240 | J15: =H15*I15 -> 0 | K15: =D15+G15+J15 -> 520 | L15: =C15+F15+I15 -> 2 | M15: 200 | N15: 24 | O15: 20 | P15: =((B15-M15)*C15)+((E15-M15)*F15)+((H15-M15)*I15) -> 120
A16: Wind Breaker | B16: 1650 | C16: 1 | D16: =B16*C16 -> 1650 | E16: 1600 | G16: =E16*F16 -> 0 | H16: 1500 | J16: =H16*I16 -> 0 | K16: =D16+G16+J16 -> 1650 | L16: =C16+F16+I16 -> 1 | M16: 1125 | N16: 135 | O16: 112.5 | P16: =((B16-M16)*C16)+((E16-M16)*F16)+((H16-M16)*I16) -> 525
C17: TOTAL | D17: =SUM(D5:D16) -> 5540 | F17: TOTAL | G17: =SUM(G5:G16) -> 0 | I17: TOTAL | J17: =SUM(J5:J16) -> 0 | K17: =D17+G17+J17 -> 5540 | M17: TOTAL | P17: =SUM(P5:P16) -> 1405
A18: JYL | B18: RETAIL PRICE | C18: PCS SOLD | D18: SALES | E18: DISCOUNTED PRICE | F18: PCS SOLD | G18: SALES | H18: SPECIAL DISC. PRICE | I18: PCS SOLD | J18: SALES | K18: TOTAL SALES | L18: TOTALQTY SOLD | M18: PRODUCTION PRICE | N18: 12% Vat | O18: 10% Mark Up | P18: PROFIT
A19: GT Shirt | B19: 375 | D19: =B19*C19 -> 0 | E19: 350 | G19: =E19*F19 -> 0 | H19: 325 | J19: =H19*I19 -> 0 | K19: =D19+G19+J19 -> 0 | L19: =C19+F19+I19 -> 0 | M19: 250 | N19: 30 | O19: 25 | P19: =((B19-M19)*C19)+((E19-M19)*F19)+((H19-M19)*I19) -> 0
A20: Jacket | B20: 1900 | C20: 2 | D20: =B20*C20 -> 3800 | E20: 1700 | F20: 1 | G20: =E20*F20 -> 1700 | H20: 1500 | J20: =H20*I20 -> 0 | K20: =D20+G20+J20 -> 5500 | L20: =C20+F20+I20 -> 3 | M20: 1200 | N20: 144 | O20: 120 | P20: =((B20-M20)*C20)+((E20-M20)*F20)+((H20-M20)*I20) -> 1900
A21: Poloshirt 123456 | B21: 860 | D21: =B21*C21 -> 0 | E21: 800 | F21: 1 | G21: =E21*F21 -> 800 | H21: 750 | J21: =H21*I21 -> 0 | K21: =D21+G21+J21 -> 800 | L21: =C21+F21+I21 -> 1 | M21: 600 | N21: 72 | O21: 60 | P21: =((B21-M21)*C21)+((E21-M21)*F21)+((H21-M21)*I21) -> 200
A22: VB Jersey w/ sig. (Phased Out) | B22: 2800 | D22: =B22*C22 -> 0 | G22: =E22*F22 -> 0 | J22: =H22*I22 -> 0 | K22: =D22+G22+J22 -> 0 | L22: =C22+F22+I22 -> 0 | M22: 800 | N22: 96 | O22: 80 | P22: =((B22-M22)*C22)+((E22-M22)*F22)+((H22-M22)*I22) -> 0
A23: VB Jersey w/o sig. | B23: 2000 | D23: =B23*C23 -> 0 | E23: 1800 | G23: =E23*F23 -> 0 | H23: 1500 | J23: =H23*I23 -> 0 | K23: =D23+G23+J23 -> 0 | L23: =C23+F23+I23 -> 0 | M23: 800 | P23: =((B23-M23)*C23)+((E23-M23)*F23)+((H23-M23)*I23) -> 0
A24: VB Jersey w/o sig. | B24: 1500 | D24: =B24*C24 -> 0 | E24: 1400 | G24: =E24*F24 -> 0 | H24: 1300 | J24: =H24*I24 -> 0 | K24: =D24+G24+J24 -> 0 | L24: =C24+F24+I24 -> 0 | M24: 800 | P24: =((B24-M24)*C24)+((E24-M24)*F24)+((H24-M24)*I24) -> 0
A25: VB Jersey w/o sig. | B25: 1000 | D25: =B25*C25 -> 0 | E25: 980 | G25: =E25*F25 -> 0 | H25: 950 | J25: =H25*I25 -> 0 | K25: =D25+G25+J25 -> 0 | L25: =C25+F25+I25 -> 0 | M25: 800 | P25: =((B25-M25)*C25)+((E25-M25)*F25)+((H25-M25)*I25) -> 0
A26: VB Jersey with sig. (Phased Out) | B26: 1500 | D26: =B26*C26 -> 0 | G26: =E26*F26 -> 0 | J26: =H26*I26 -> 0 | K26: =D26+G26+J26 -> 0 | L26: =C26+F26+I26 -> 0 | M26: 800 | P26: =((B26-M26)*C26)+((E26-M26)*F26)+((H26-M26)*I26) -> 0
C27: TOTAL | D27: =SUM(D19:D26) -> 3800 | F27: TOTAL | G27: =SUM(G19:G26) -> 2500 | I27: TOTAL | J27: =SUM(J19:J26) -> 0 | K27: =D27+G27+J27 -> 6300 | M27: TOTAL | P27: =SUM(P19:P26) -> 2100
A28: JUC | B28: RETAIL PRICE | C28: PCS SOLD | D28: SALES | E28: DISCOUNTED PRICE | F28: PCS SOLD | G28: SALES | H28: SPECIAL DISC. PRICE | I28: PCS SOLD | J28: SALES | K28: TOTAL SALES | L28: TOTALQTY SOLD | M28: PRODUCTION PRICE | N28: 12% Vat | O28: 10% Mark Up | P28: PROFIT
A29: UST OAT Hoodie Jacket | B29: 1450 | D29: =B29*C29 -> 0 | E29: 1400 | G29: =E29*F29 -> 0 | H29: 1300 | I29: 1 | J29: =H29*I29 -> 1300 | K29: =D29+G29+J29 -> 1300 | L29: =C29+F29+I29 -> 1 | M29: 1000 | N29: 120 | O29: 100 | P29: =((B29-M29)*C29)+((E29-M29)*F29)+((H29-M29)*I29) -> 300
A30: UST OAT MUG | B30: 150 | C30: 2 | D30: =B30*C30 -> 300 | E30: 140 | G30: =E30*F30 -> 0 | H30: 135 | J30: =H30*I30 -> 0 | K30: =D30+G30+J30 -> 300 | L30: =C30+F30+I30 -> 2 | M30: 110 | N30: 12 | O30: 10 | P30: =((B30-M30)*C30)+((E30-M30)*F30)+((H30-M30)*I30) -> 80
A31: UST OAT MUG (WE) Inside | B31: 150 | C31: 1 | D31: =B31*C31 -> 150 | E31: 140 | G31: =E31*F31 -> 0 | H31: 135 | J31: =H31*I31 -> 0 | K31: =D31+G31+J31 -> 150 | L31: =C31+F31+I31 -> 1 | M31: 100 | N31: 12 | O31: 10 | P31: =((B31-M31)*C31)+((E31-M31)*F31)+((H31-M31)*I31) -> 50
A32: UST OAT T-Shirt | B32: 375 | D32: =B32*C32 -> 0 | E32: 360 | G32: =E32*F32 -> 0 | H32: 340 | J32: =H32*I32 -> 0 | K32: =D32+G32+J32 -> 0 | L32: =C32+F32+I32 -> 0 | M32: 280 | N32: 33.6 | O32: 28 | P32: =((B32-M32)*C32)+((E32-M32)*F32)+((H32-M32)*I32) -> 0
A33: UST T-Shirt Sports | B33: 430 | C33: 5 | D33: =B33*C33 -> 2150 | E33: 400 | G33: =E33*F33 -> 0 | H33: 350 | J33: =H33*I33 -> 0 | K33: =D33+G33+J33 -> 2150 | L33: =C33+F33+I33 -> 5 | M33: 260 | N33: 31.2 | O33: 26 | P33: =((B33-M33)*C33)+((E33-M33)*F33)+((H33-M33)*I33) -> 850
A34: UST T-Shirt Tiger Pattern | B34: 450 | D34: =B34*C34 -> 0 | E34: 430 | G34: =E34*F34 -> 0 | H34: 400 | J34: =H34*I34 -> 0 | K34: =D34+G34+J34 -> 0 | L34: =C34+F34+I34 -> 0 | M34: 330 | N34: 39.6 | O34: 33 | P34: =((B34-M34)*C34)+((E34-M34)*F34)+((H34-M34)*I34) -> 0
A35: UST Happy Tiger | B35: 450 | C35: 2 | D35: =B35*C35 -> 900 | E35: 400 | G35: =E35*F35 -> 0 | H35: 375 | J35: =H35*I35 -> 0 | K35: =D35+G35+J35 -> 900 | L35: =C35+F35+I35 -> 2 | M35: 280 | N35: 33.6 | O35: 28 | P35: =((B35-M35)*C35)+((E35-M35)*F35)+((H35-M35)*I35) -> 340
A36: OAT Tote Bag (Phased Out) | B36: 220 | D36: =B36*C36 -> 0 | G36: =E36*F36 -> 0 | J36: =H36*I36 -> 0 | K36: =D36+G36+J36 -> 0 | L36: =C36+F36+I36 -> 0 | M36: 120 | P36: =((B36-M36)*C36)+((E36-M36)*F36)+((H36-M36)*I36) -> 0
C37: TOTAL | D37: =SUM(D29:D36) -> 3500 | F37: TOTAL | G37: =SUM(G29:G36) -> 0 | I37: TOTAL | J37: =SUM(J29:J36) -> 1300 | K37: =D37+G37+J37 -> 4800 | M37: TOTAL | P37: =SUM(P29:P36) -> 1620
A38: USTORE | B38: RETAIL PRICE | C38: PCS SOLD | D38: SALES | E38: DISCOUNTED PRICE | F38: PCS SOLD | G38: SALES | H38: SPECIAL DISC. PRICE | I38: PCS SOLD | J38: SALES | K38: TOTAL SALES | L38: TOTALQTY SOLD | M38: PRODUCTION PRICE | N38: 12% Vat | O38: 10% Mark Up | P38: PROFIT
A39: Auto Umbrella | B39: 250 | D39: =B39*C39 -> 0 | G39: =E39*F39 -> 0 | J39: =H39*I39 -> 0 | K39: =D39+G39+J39 -> 0 | L39: =C39+F39+I39 -> 0 | P39: =((B39-M39)*C39)+((E39-M39)*F39)+((H39-M39)*I39) -> 0
A40: Bag | B40: 250 | D40: =B40*C40 -> 0 | G40: =E40*F40 -> 0 | J40: =H40*I40 -> 0 | K40: =D40+G40+J40 -> 0 | L40: =C40+F40+I40 -> 0 | P40: =((B40-M40)*C40)+((E40-M40)*F40)+((H40-M40)*I40) -> 0
...

Sheet May 7
A1: DAILY SALES REPORT
A2: 45415
A3: ITEMS | B3: RETAIL PRICE | C3: PCS SOLD | D3: SALES | E3: DISCOUNTED PRICE | F3: PCS SOLD | G3: SALES | H3: SPECIAL DISC. PRICE | I3: PCS SOLD | J3: SALES | K3: TOTAL SALES | L3: TOTALQTY SOLD | M3: PRODUCTION PRICE | N3: 12% Vat | O3: 10% Mark Up | P3: PROFIT
A4: NAPOLIZ
A5: Backpack Bag | B5: 1750 | C5: 1 | D5: =B5*C5 -> 1750 | E5: 1600 | G5: =E5*F5 -> 0 | H5: 1400 | J5: =H5*I5 -> 0 | K5: =D5+G5+J5 -> 1750 | L5: =C5+F5+I5 -> 1 | M5: 840 | N5: 100.8 | O5: 84 | P5: =((B5-M5)*C5)+((E5-M5)*F5)+((H5-M5)*I5) -> 910
A6: Black Tote Bag (Phased Out) | B6: 280 | D6: =B6*C6 -> 0 | G6: =E6*F6 -> 0 | J6: =H6*I6 -> 0 | K6: =D6+G6+J6 -> 0 | L6: =C6+F6+I6 -> 0 | M6: 230 | P6: =((B6-M6)*C6)+((E6-M6)*F6)+((H6-M6)*I6) -> 0
A7: Double Canopy | B7: 639 | D7: =B7*C7 -> 0 | E7: 575 | G7: =E7*F7 -> 0 | H7: 500 | J7: =H7*I7 -> 0 | K7: =D7+G7+J7 -> 0 | L7: =C7+F7+I7 -> 0 | M7: 330 | N7: 39.6 | O7: 33 | P7: =((B7-M7)*C7)+((E7-M7)*F7)+((H7-M7)*I7) -> 0
A8: Laptop Bag | B8: 1450 | D8: =B8*C8 -> 0 | E8: 1400 | G8: =E8*F8 -> 0 | H8: 1250 | J8: =H8*I8 -> 0 | K8: =D8+G8+J8 -> 0 | L8: =C8+F8+I8 -> 0 | M8: 840 | N8: 100.8 | O8: 84 | P8: =((B8-M8)*C8)+((E8-M8)*F8)+((H8-M8)*I8) -> 0
A9: Script Santo Tomas with Tiger Back (B) | B9: 480 | C9: 1 | D9: =B9*C9 -> 480 | E9: 460 | G9: =E9*F9 -> 0 | H9: 450 | J9: =H9*I9 -> 0 | K9: =D9+G9+J9 -> 480 | L9: =C9+F9+I9 -> 1 | M9: 360 | N9: 43.2 | O9: 36 | P9: =((B9-M9)*C9)+((E9-M9)*F9)+((H9-M9)*I9) -> 120
A10: Side Tiger Hoodie | B10: 1480 | D10: =B10*C10 -> 0 | E10: 1400 | G10: =E10*F10 -> 0 | H10: 1375 | J10: =H10*I10 -> 0 | K10: =D10+G10+J10 -> 0 | L10: =C10+F10+I10 -> 0 | M10: 1125 | N10: 135 | O10: 112.5 | P10: =((B10-M10)*C10)+((E10-M10)*F10)+((H10-M10)*I10) -> 0
A11: Sling Bag | B11: 330 | D11: =B11*C11 -> 0 | E11: 320 | G11: =E11*F11 -> 0 | H11: 300 | J11: =H11*I11 -> 0 | K11: =D11+G11+J11 -> 0 | L11: =C11+F11+I11 -> 0 | M11: 260 | N11: 31.2 | O11: 26 | P11: =((B11-M11)*C11)+((E11-M11)*F11)+((H11-M11)*I11) -> 0
A12: Front Tiger Hoodie | B12: 1440 | D12: =B12*C12 -> 0 | E12: 1400 | G12: =E12*F12 -> 0 | H12: 1375 | J12: =H12*I12 -> 0 | K12: =D12+G12+J12 -> 0 | L12: =C12+F12+I12 -> 0 | M12: 1125 | N12: 135 | O12: 112.5 | P12: =((B12-M12)*C12)+((E12-M12)*F12)+((H12-M12)*I12) -> 0
A13: University of Santo Tomas (B) | B13: 450 | C13: 1 | D13: =B13*C13 -> 450 | E13: 440 | G13: =E13*F13 -> 0 | H13: 425 | J13: =H13*I13 -> 0 | K13: =D13+G13+J13 -> 450 | L13: =C13+F13+I13 -> 1 | M13: 360 | N13: 43.2 | O13: 36 | P13: =((B13-M13)*C13)+((E13-M13)*F13)+((H13-M13)*I13) -> 90
A14: UST Tiger Front and Back Graphic (W) | B14: 500 | D14: =B14*C14 -> 0 | E14: 480 | G14: =E14*F14 -> 0 | H14: 450 | J14: =H14*I14 -> 0 | K14: =D14+G14+J14 -> 0 | L14: =C14+F14+I14 -> 0 | M14: 360 | N14: 43.2 | O14: 36 | P14: =((B14-M14)*C14)+((E14-M14)*F14)+((H14-M14)*I14) -> 0
A15: White Tote Bag | B15: 260 | D15: =B15*C15 -> 0 | E15: 250 | G15: =E15*F15 -> 0 | H15: 240 | J15: =H15*I15 -> 0 | K15: =D15+G15+J15 -> 0 | L15: =C15+F15+I15 -> 0 | M15: 200 | N15: 24 | O15: 20 | P15: =((B15-M15)*C15)+((E15-M15)*F15)+((H15-M15)*I15) -> 0
A16: Wind Breaker | B16: 1650 | C16: 2 | D16: =B16*C16 -> 3300 | E16: 1600 | G16: =E16*F16 -> 0 | H16: 1500 | J16: =H16*I16 -> 0 | K16: =D16+G16+J16 -> 3300 | L16: =C16+F16+I16 -> 2 | M16: 1125 | N16: 135 | O16: 112.5 | P16: =((B16-M16)*C16)+((E16-M16)*F16)+((H16-M16)*I16) -> 1050
C17: TOTAL | D17: =SUM(D5:D16) -> 5980 | F17: TOTAL | G17: =SUM(G5:G16) -> 0 | I17: TOTAL | J17: =SUM(J5:J16) -> 0 | K17: =D17+G17+J17 -> 5980 | M17: TOTAL | P17: =SUM(P5:P16) -> 2170
A18: JYL | B18: RETAIL PRICE | C18: PCS SOLD | D18: SALES | E18: DISCOUNTED PRICE | F18: PCS SOLD | G18: SALES | H18: SPECIAL DISC. PRICE | I18: PCS SOLD | J18: SALES | K18: TOTAL SALES | L18: TOTALQTY SOLD | M18: PRODUCTION PRICE | N18: 12% Vat | O18: 10% Mark Up | P18: PROFIT
A19: GT Shirt | B19: 375 | D19: =B19*C19 -> 0 | E19: 350 | G19: =E19*F19 -> 0 | H19: 325 | J19: =H19*I19 -> 0 | K19: =D19+G19+J19 -> 0 | L19: =C19+F19+I19 -> 0 | M19: 250 | N19: 30 | O19: 25 | P19: =((B19-M19)*C19)+((E19-M19)*F19)+((H19-M19)*I19) -> 0
A20: Jacket | B20: 1900 | C20: 2 | D20: =B20*C20 -> 3800 | E20: 1700 | G20: =E20*F20 -> 0 | H20: 1500 | J20: =H20*I20 -> 0 | K20: =D20+G20+J20 -> 3800 | L20: =C20+F20+I20 -> 2 | M20: 1200 | N20: 144 | O20: 120 | P20: =((B20-M20)*C20)+((E20-M20)*F20)+((H20-M20)*I20) -> 1400
A21: Poloshirt 123456 | B21: 860 | D21: =B21*C21 -> 0 | E21: 800 | G21: =E21*F21 -> 0 | H21: 750 | J21: =H21*I21 -> 0 | K21: =D21+G21+J21 -> 0 | L21: =C21+F21+I21 -> 0 | M21: 600 | N21: 72 | O21: 60 | P21: =((B21-M21)*C21)+((E21-M21)*F21)+((H21-M21)*I21) -> 0
A22: VB Jersey w/ sig. (Phased Out) | B22: 2800 | D22: =B22*C22 -> 0 | G22: =E22*F22 -> 0 | J22: =H22*I22 -> 0 | K22: =D22+G22+J22 -> 0 | L22: =C22+F22+I22 -> 0 | M22: 800 | N22: 96 | O22: 80 | P22: =((B22-M22)*C22)+((E22-M22)*F22)+((H22-M22)*I22) -> 0
A23: VB Jersey w/o sig. | B23: 2000 | D23: =B23*C23 -> 0 | E23: 1800 | G23: =E23*F23 -> 0 | H23: 1500 | J23: =H23*I23 -> 0 | K23: =D23+G23+J23 -> 0 | L23: =C23+F23+I23 -> 0 | M23: 800 | P23: =((B23-M23)*C23)+((E23-M23)*F23)+((H23-M23)*I23) -> 0
A24: VB Jersey w/o sig. | B24: 1500 | D24: =B24*C24 -> 0 | E24: 1400 | G24: =E24*F24 -> 0 | H24: 1300 | J24: =H24*I24 -> 0 | K24: =D24+G24+J24 -> 0 | L24: =C24+F24+I24 -> 0 | M24: 800 | P24: =((B24-M24)*C24)+((E24-M24)*F24)+((H24-M24)*I24) -> 0
A25: VB Jersey w/o sig. | B25: 1000 | D25: =B25*C25 -> 0 | E25: 980 | G25: =E25*F25 -> 0 | H25: 950 | J25: =H25*I25 -> 0 | K25: =D25+G25+J25 -> 0 | L25: =C25+F25+I25 -> 0 | M25: 800 | P25: =((B25-M25)*C25)+((E25-M25)*F25)+((H25-M25)*I25) -> 0
A26: VB Jersey with sig. (Phased Out) | B26: 1500 | D26: =B26*C26 -> 0 | G26: =E26*F26 -> 0 | J26: =H26*I26 -> 0 | K26: =D26+G26+J26 -> 0 | L26: =C26+F26+I26 -> 0 | M26: 800 | P26: =((B26-M26)*C26)+((E26-M26)*F26)+((H26-M26)*I26) -> 0
C27: TOTAL | D27: =SUM(D19:D26) -> 3800 | F27: TOTAL | G27: =SUM(G19:G26) -> 0 | I27: TOTAL | J27: =SUM(J19:J26) -> 0 | K27: =D27+G27+J27 -> 3800 | M27: TOTAL | P27: =SUM(P19:P26) -> 1400
A28: JUC | B28: RETAIL PRICE | C28: PCS SOLD | D28: SALES | E28: DISCOUNTED PRICE | F28: PCS SOLD | G28: SALES | H28: SPECIAL DISC. PRICE | I28: PCS SOLD | J28: SALES | K28: TOTAL SALES | L28: TOTALQTY SOLD | M28: PRODUCTION PRICE | N28: 12% Vat | O28: 10% Mark Up | P28: PROFIT
A29: UST OAT Hoodie Jacket | B29: 1450 | C29: 3 | D29: =B29*C29 -> 4350 | E29: 1400 | G29: =E29*F29 -> 0 | H29: 1300 | J29: =H29*I29 -> 0 | K29: =D29+G29+J29 -> 4350 | L29: =C29+F29+I29 -> 3 | M29: 1000 | N29: 120 | O29: 100 | P29: =((B29-M29)*C29)+((E29-M29)*F29)+((H29-M29)*I29) -> 1350
A30: UST OAT MUG | B30: 150 | C30: 13 | D30: =B30*C30 -> 1950 | E30: 140 | G30: =E30*F30 -> 0 | H30: 135 | J30: =H30*I30 -> 0 | K30: =D30+G30+J30 -> 1950 | L30: =C30+F30+I30 -> 13 | M30: 110 | N30: 12 | O30: 10 | P30: =((B30-M30)*C30)+((E30-M30)*F30)+((H30-M30)*I30) -> 520
A31: UST OAT MUG (WE) Inside | B31: 150 | C31: 7 | D31: =B31*C31 -> 1050 | E31: 140 | G31: =E31*F31 -> 0 | H31: 135 | J31: =H31*I31 -> 0 | K31: =D31+G31+J31 -> 1050 | L31: =C31+F31+I31 -> 7 | M31: 100 | N31: 12 | O31: 10 | P31: =((B31-M31)*C31)+((E31-M31)*F31)+((H31-M31)*I31) -> 350
A32: UST OAT T-Shirt | B32: 375 | C32: 1 | D32: =B32*C32 -> 375 | E32: 360 | G32: =E32*F32 -> 0 | H32: 340 | J32: =H32*I32 -> 0 | K32: =D32+G32+J32 -> 375 | L32: =C32+F32+I32 -> 1 | M32: 280 | N32: 33.6 | O32: 28 | P32: =((B32-M32)*C32)+((E32-M32)*F32)+((H32-M32)*I32) -> 95
A33: UST T-Shirt Sports | B33: 430 | C33: 4 | D33: =B33*C33 -> 1720 | E33: 400 | G33: =E33*F33 -> 0 | H33: 350 | J33: =H33*I33 -> 0 | K33: =D33+G33+J33 -> 1720 | L33: =C33+F33+I33 -> 4 | M33: 260 | N33: 31.2 | O33: 26 | P33: =((B33-M33)*C33)+((E33-M33)*F33)+((H33-M33)*I33) -> 680
A34: UST T-Shirt Tiger Pattern | B34: 450 | C34: 4 | D34: =B34*C34 -> 1800 | E34: 430 | G34: =E34*F34 -> 0 | H34: 400 | J34: =H34*I34 -> 0 | K34: =D34+G34+J34 -> 1800 | L34: =C34+F34+I34 -> 4 | M34: 330 | N34: 39.6 | O34: 33 | P34: =((B34-M34)*C34)+((E34-M34)*F34)+((H34-M34)*I34) -> 480
A35: UST Happy Tiger | B35: 450 | C35: 2 | D35: =B35*C35 -> 900 | E35: 400 | G35: =E35*F35 -> 0 | H35: 375 | J35: =H35*I35 -> 0 | K35: =D35+G35+J35 -> 900 | L35: =C35+F35+I35 -> 2 | M35: 280 | N35: 33.6 | O35: 28 | P35: =((B35-M35)*C35)+((E35-M35)*F35)+((H35-M35)*I35) -> 340
A36: OAT Tote Bag (Phased Out) | B36: 220 | D36: =B36*C36 -> 0 | G36: =E36*F36 -> 0 | J36: =H36*I36 -> 0 | K36: =D36+G36+J36 -> 0 | L36: =C36+F36+I36 -> 0 | M36: 120 | P36: =((B36-M36)*C36)+((E36-M36)*F36)+((H36-M36)*I36) -> 0
C37: TOTAL | D37: =SUM(D29:D36) -> 12145 | F37: TOTAL | G37: =SUM(G29:G36) -> 0 | I37: TOTAL | J37: =SUM(J29:J36) -> 0 | K37: =D37+G37+J37 -> 12145 | L37: =SUM(L29:L36) -> 34 | M37: TOTAL | P37: =SUM(P29:P36) -> 3815
A38: USTORE | B38: RETAIL PRICE | C38: PCS SOLD | D38: SALES | E38: DISCOUNTED PRICE | F38: PCS SOLD | G38: SALES | H38: SPECIAL DISC. PRICE | I38: PCS SOLD | J38: SALES | K38: TOTAL SALES | L38: TOTALQTY SOLD | M38: PRODUCTION PRICE | N38: 12% Vat | O38: 10% Mark Up | P38: PROFIT
A39: Auto Umbrella | B39: 250 | D39: =B39*C39 -> 0 | G39: =E39*F39 -> 0 | J39: =H39*I39 -> 0 | K39: =D39+G39+J39 -> 0 | L39: =C39+F39+I39 -> 0 | P39: =((B39-M39)*C39)+((E39-M39)*F39)+((H39-M39)*I39) -> 0
A40: Bag | B40: 250 | D40: =B40*C40 -> 0 | E40: 150 | F40: 26 | G40: =E40*F40 -> 3900 | J40: =H40*I40 -> 0 | K40: =D40+G40+J40 -> 3900 | L40: =C40+F40+I40 -> 26 | P40: =((B40-M40)*C40)+((E40-M40)*F40)+((H40-M40)*I40) -> 3900
...

Sheet May 8
A1: DAILY SALES REPORT
A2: 45420
A3: ITEMS | B3: RETAIL PRICE | C3: PCS SOLD | D3: SALES | E3: DISCOUNTED PRICE | F3: PCS SOLD | G3: SALES | H3: SPECIAL DISC. PRICE | I3: PCS SOLD | J3: SALES | K3: TOTAL SALES | L3: TOTALQTY SOLD | M3: PRODUCTION PRICE | N3: 12% Vat | O3: 10% Mark Up | P3: PROFIT
A4: NAPOLIZ
A5: Backpack Bag | B5: 1750 | D5: =B5*C5 -> 0 | E5: 1600 | G5: =E5*F5 -> 0 | H5: 1400 | J5: =H5*I5 -> 0 | K5: =D5+G5+J5 -> 0 | L5: =C5+F5+I5 -> 0 | M5: 840 | N5: 100.8 | O5: 84 | P5: =((B5-M5)*C5)+((E5-M5)*F5)+((H5-M5)*I5) -> 0
A6: Black Tote Bag (Phased Out) | B6: 280 | D6: =B6*C6 -> 0 | G6: =E6*F6 -> 0 | J6: =H6*I6 -> 0 | K6: =D6+G6+J6 -> 0 | L6: =C6+F6+I6 -> 0 | M6: 230 | P6: =((B6-M6)*C6)+((E6-M6)*F6)+((H6-M6)*I6) -> 0
A7: Double Canopy | B7: 639 | D7: =B7*C7 -> 0 | E7: 575 | G7: =E7*F7 -> 0 | H7: 500 | J7: =H7*I7 -> 0 | K7: =D7+G7+J7 -> 0 | L7: =C7+F7+I7 -> 0 | M7: 330 | N7: 39.6 | O7: 33 | P7: =((B7-M7)*C7)+((E7-M7)*F7)+((H7-M7)*I7) -> 0
A8: Laptop Bag | B8: 1450 | D8: =B8*C8 -> 0 | E8: 1400 | G8: =E8*F8 -> 0 | H8: 1250 | J8: =H8*I8 -> 0 | K8: =D8+G8+J8 -> 0 | L8: =C8+F8+I8 -> 0 | M8: 840 | N8: 100.8 | O8: 84 | P8: =((B8-M8)*C8)+((E8-M8)*F8)+((H8-M8)*I8) -> 0
A9: Script Santo Tomas with Tiger Back (B) | B9: 480 | C9: 2 | D9: =B9*C9 -> 960 | E9: 460 | G9: =E9*F9 -> 0 | H9: 450 | J9: =H9*I9 -> 0 | K9: =D9+G9+J9 -> 960 | L9: =C9+F9+I9 -> 2 | M9: 360 | N9: 43.2 | O9: 36 | P9: =((B9-M9)*C9)+((E9-M9)*F9)+((H9-M9)*I9) -> 240
A10: Side Tiger Hoodie | B10: 1480 | C10: 1 | D10: =B10*C10 -> 1480 | E10: 1400 | G10: =E10*F10 -> 0 | H10: 1375 | J10: =H10*I10 -> 0 | K10: =D10+G10+J10 -> 1480 | L10: =C10+F10+I10 -> 1 | M10: 1125 | N10: 135 | O10: 112.5 | P10: =((B10-M10)*C10)+((E10-M10)*F10)+((H10-M10)*I10) -> 355
A11: Sling Bag | B11: 330 | D11: =B11*C11 -> 0 | E11: 320 | G11: =E11*F11 -> 0 | H11: 300 | J11: =H11*I11 -> 0 | K11: =D11+G11+J11 -> 0 | L11: =C11+F11+I11 -> 0 | M11: 260 | N11: 31.2 | O11: 26 | P11: =((B11-M11)*C11)+((E11-M11)*F11)+((H11-M11)*I11) -> 0
A12: Front Tiger Hoodie | B12: 1440 | D12: =B12*C12 -> 0 | E12: 1400 | G12: =E12*F12 -> 0 | H12: 1375 | J12: =H12*I12 -> 0 | K12: =D12+G12+J12 -> 0 | L12: =C12+F12+I12 -> 0 | M12: 1125 | N12: 135 | O12: 112.5 | P12: =((B12-M12)*C12)+((E12-M12)*F12)+((H12-M12)*I12) -> 0
A13: University of Santo Tomas (B) | B13: 450 | C13: 15 | D13: =B13*C13 -> 6750 | E13: 440 | G13: =E13*F13 -> 0 | H13: 425 | J13: =H13*I13 -> 0 | K13: =D13+G13+J13 -> 6750 | L13: =C13+F13+I13 -> 15 | M13: 360 | N13: 43.2 | O13: 36 | P13: =((B13-M13)*C13)+((E13-M13)*F13)+((H13-M13)*I13) -> 1350
A14: UST Tiger Front and Back Graphic (W) | B14: 500 | C14: 1 | D14: =B14*C14 -> 500 | E14: 480 | G14: =E14*F14 -> 0 | H14: 450 | J14: =H14*I14 -> 0 | K14: =D14+G14+J14 -> 500 | L14: =C14+F14+I14 -> 1 | M14: 360 | N14: 43.2 | O14: 36 | P14: =((B14-M14)*C14)+((E14-M14)*F14)+((H14-M14)*I14) -> 140
A15: White Tote Bag | B15: 260 | D15: =B15*C15 -> 0 | E15: 250 | G15: =E15*F15 -> 0 | H15: 240 | J15: =H15*I15 -> 0 | K15: =D15+G15+J15 -> 0 | L15: =C15+F15+I15 -> 0 | M15: 200 | N15: 24 | O15: 20 | P15: =((B15-M15)*C15)+((E15-M15)*F15)+((H15-M15)*I15) -> 0
A16: Wind Breaker | B16: 1650 | C16: 6 | D16: =B16*C16 -> 9900 | E16: 1600 | G16: =E16*F16 -> 0 | H16: 1500 | J16: =H16*I16 -> 0 | K16: =D16+G16+J16 -> 9900 | L16: =C16+F16+I16 -> 6 | M16: 1125 | N16: 135 | O16: 112.5 | P16: =((B16-M16)*C16)+((E16-M16)*F16)+((H16-M16)*I16) -> 3150
C17: TOTAL | D17: =SUM(D5:D16) -> 19590 | F17: TOTAL | G17: =SUM(G5:G16) -> 0 | I17: TOTAL | J17: =SUM(J5:J16) -> 0 | K17: =D17+G17+J17 -> 19590 | M17: TOTAL | P17: =SUM(P5:P16) -> 5235
A18: JYL | B18: RETAIL PRICE | C18: PCS SOLD | D18: SALES | E18: DISCOUNTED PRICE | F18: PCS SOLD | G18: SALES | H18: SPECIAL DISC. PRICE | I18: PCS SOLD | J18: SALES | K18: TOTAL SALES | L18: TOTALQTY SOLD | M18: PRODUCTION PRICE | N18: 12% Vat | O18: 10% Mark Up | P18: PROFIT
A19: GT Shirt | B19: 375 | D19: =B19*C19 -> 0 | E19: 350 | G19: =E19*F19 -> 0 | H19: 325 | J19: =H19*I19 -> 0 | K19: =D19+G19+J19 -> 0 | L19: =C19+F19+I19 -> 0 | M19: 250 | N19: 30 | O19: 25 | P19: =((B19-M19)*C19)+((E19-M19)*F19)+((H19-M19)*I19) -> 0
A20: Jacket | B20: 1900 | C20: 1 | D20: =B20*C20 -> 1900 | E20: 1700 | G20: =E20*F20 -> 0 | H20: 1500 | J20: =H20*I20 -> 0 | K20: =D20+G20+J20 -> 1900 | L20: =C20+F20+I20 -> 1 | M20: 1200 | N20: 144 | O20: 120 | P20: =((B20-M20)*C20)+((E20-M20)*F20)+((H20-M20)*I20) -> 700
A21: Poloshirt 123456 | B21: 860 | D21: =B21*C21 -> 0 | E21: 800 | G21: =E21*F21 -> 0 | H21: 750 | J21: =H21*I21 -> 0 | K21: =D21+G21+J21 -> 0 | L21: =C21+F21+I21 -> 0 | M21: 600 | N21: 72 | O21: 60 | P21: =((B21-M21)*C21)+((E21-M21)*F21)+((H21-M21)*I21) -> 0
A22: VB Jersey w/ sig. (Phased Out) | B22: 2800 | D22: =B22*C22 -> 0 | G22: =E22*F22 -> 0 | J22: =H22*I22 -> 0 | K22: =D22+G22+J22 -> 0 | L22: =C22+F22+I22 -> 0 | M22: 800 | N22: 96 | O22: 80 | P22: =((B22-M22)*C22)+((E22-M22)*F22)+((H22-M22)*I22) -> 0
A23: VB Jersey w/o sig. | B23: 2000 | D23: =B23*C23 -> 0 | E23: 1800 | G23: =E23*F23 -> 0 | H23: 1500 | J23: =H23*I23 -> 0 | K23: =D23+G23+J23 -> 0 | L23: =C23+F23+I23 -> 0 | M23: 800 | P23: =((B23-M23)*C23)+((E23-M23)*F23)+((H23-M23)*I23) -> 0
A24: VB Jersey w/o sig. | B24: 1500 | D24: =B24*C24 -> 0 | E24: 1400 | G24: =E24*F24 -> 0 | H24: 1300 | J24: =H24*I24 -> 0 | K24: =D24+G24+J24 -> 0 | L24: =C24+F24+I24 -> 0 | M24: 800 | P24: =((B24-M24)*C24)+((E24-M24)*F24)+((H24-M24)*I24) -> 0
A25: VB Jersey w/o sig. | B25: 1000 | D25: =B25*C25 -> 0 | E25: 980 | G25: =E25*F25 -> 0 | H25: 950 | J25: =H25*I25 -> 0 | K25: =D25+G25+J25 -> 0 | L25: =C25+F25+I25 -> 0 | M25: 800 | P25: =((B25-M25)*C25)+((E25-M25)*F25)+((H25-M25)*I25) -> 0
A26: VB Jersey with sig. (Phased Out) | B26: 1500 | D26: =B26*C26 -> 0 | G26: =E26*F26 -> 0 | J26: =H26*I26 -> 0 | K26: =D26+G26+J26 -> 0 | L26: =C26+F26+I26 -> 0 | M26: 800 | P26: =((B26-M26)*C26)+((E26-M26)*F26)+((H26-M26)*I26) -> 0
C27: TOTAL | D27: =SUM(D19:D26) -> 1900 | F27: TOTAL | G27: =SUM(G19:G26) -> 0 | I27: TOTAL | J27: =SUM(J19:J26) -> 0 | K27: =D27+G27+J27 -> 1900 | M27: TOTAL | P27: =SUM(P19:P26) -> 700
A28: JUC | B28: RETAIL PRICE | C28: PCS SOLD | D28: SALES | E28: DISCOUNTED PRICE | F28: PCS SOLD | G28: SALES | H28: SPECIAL DISC. PRICE | I28: PCS SOLD | J28: SALES | K28: TOTAL SALES | L28: TOTALQTY SOLD | M28: PRODUCTION PRICE | N28: 12% Vat | O28: 10% Mark Up | P28: PROFIT
A29: UST OAT Hoodie Jacket | B29: 1450 | D29: =B29*C29 -> 0 | E29: 1400 | G29: =E29*F29 -> 0 | H29: 1300 | J29: =H29*I29 -> 0 | K29: =D29+G29+J29 -> 0 | L29: =C29+F29+I29 -> 0 | M29: 1000 | N29: 120 | O29: 100 | P29: =((B29-M29)*C29)+((E29-M29)*F29)+((H29-M29)*I29) -> 0
A30: UST OAT MUG | B30: 150 | C30: 2 | D30: =B30*C30 -> 300 | E30: 140 | G30: =E30*F30 -> 0 | H30: 135 | J30: =H30*I30 -> 0 | K30: =D30+G30+J30 -> 300 | L30: =C30+F30+I30 -> 2 | M30: 110 | N30: 12 | O30: 10 | P30: =((B30-M30)*C30)+((E30-M30)*F30)+((H30-M30)*I30) -> 80
A31: UST OAT MUG (WE) Inside | B31: 150 | C31: 1 | D31: =B31*C31 -> 150 | E31: 140 | G31: =E31*F31 -> 0 | H31: 135 | J31: =H31*I31 -> 0 | K31: =D31+G31+J31 -> 150 | L31: =C31+F31+I31 -> 1 | M31: 100 | N31: 12 | O31: 10 | P31: =((B31-M31)*C31)+((E31-M31)*F31)+((H31-M31)*I31) -> 50
A32: UST OAT T-Shirt | B32: 375 | C32: 2 | D32: =B32*C32 -> 750 | E32: 360 | G32: =E32*F32 -> 0 | H32: 340 | J32: =H32*I32 -> 0 | K32: =D32+G32+J32 -> 750 | L32: =C32+F32+I32 -> 2 | M32: 280 | N32: 33.6 | O32: 28 | P32: =((B32-M32)*C32)+((E32-M32)*F32)+((H32-M32)*I32) -> 190
A33: UST T-Shirt Sports | B33: 430 | C33: 14 | D33: =B33*C33 -> 6020 | E33: 400 | F33: 2 | G33: =E33*F33 -> 800 | H33: 350 | I33: 1 | J33: =H33*I33 -> 350 | K33: =D33+G33+J33 -> 7170 | L33: =C33+F33+I33 -> 17 | M33: 260 | N33: 31.2 | O33: 26 | P33: =((B33-M33)*C33)+((E33-M33)*F33)+((H33-M33)*I33) -> 2750
A34: UST T-Shirt Tiger Pattern | B34: 450 | C34: 14 | D34: =B34*C34 -> 6300 | E34: 430 | G34: =E34*F34 -> 0 | H34: 400 | J34: =H34*I34 -> 0 | K34: =D34+G34+J34 -> 6300 | L34: =C34+F34+I34 -> 14 | M34: 330 | N34: 39.6 | O34: 33 | P34: =((B34-M34)*C34)+((E34-M34)*F34)+((H34-M34)*I34) -> 1680
A35: UST Happy Tiger | B35: 450 | C35: 11 | D35: =B35*C35 -> 4950 | E35: 400 | G35: =E35*F35 -> 0 | H35: 375 | J35: =H35*I35 -> 0 | K35: =D35+G35+J35 -> 4950 | L35: =C35+F35+I35 -> 11 | M35: 280 | N35: 33.6 | O35: 28 | P35: =((B35-M35)*C35)+((E35-M35)*F35)+((H35-M35)*I35) -> 1870
A36: OAT Tote Bag (Phased Out) | B36: 220 | D36: =B36*C36 -> 0 | G36: =E36*F36 -> 0 | J36: =H36*I36 -> 0 | K36: =D36+G36+J36 -> 0 | L36: =C36+F36+I36 -> 0 | M36: 120 | P36: =((B36-M36)*C36)+((E36-M36)*F36)+((H36-M36)*I36) -> 0
C37: TOTAL | D37: =SUM(D29:D36) -> 18470 | F37: TOTAL | G37: =SUM(G29:G36) -> 800 | I37: TOTAL | J37: =SUM(J29:J36) -> 350 | K37: =D37+G37+J37 -> 19620 | M37: TOTAL | P37: =SUM(P29:P36) -> 6620
A38: USTORE | B38: RETAIL PRICE | C38: PCS SOLD | D38: SALES | E38: DISCOUNTED PRICE | F38: PCS SOLD | G38: SALES | H38: SPECIAL DISC. PRICE | I38: PCS SOLD | J38: SALES | K38: TOTAL SALES | L38: TOTALQTY SOLD | M38: PRODUCTION PRICE | N38: 12% Vat | O38: 10% Mark Up | P38: PROFIT
A39: Auto Umbrella | B39: 250 | D39: =B39*C39 -> 0 | G39: =E39*F39 -> 0 | J39: =H39*I39 -> 0 | K39: =D39+G39+J39 -> 0 | L39: =C39+F39+I39 -> 0 | P39: =((B39-M39)*C39)+((E39-M39)*F39)+((H39-M39)*I39) -> 0
A40: Bag | B40: 250 | D40: =B40*C40 -> 0 | E40: 150 | G40: =E40*F40 -> 0 | J40: =H40*I40 -> 0 | K40: =D40+G40+J40 -> 0 | L40: =C40+F40+I40 -> 0 | P40: =((B40-M40)*C40)+((E40-M40)*F40)+((H40-M40)*I40) -> 0
...

Sheet May 9
A1: DAILY SALES REPORT
A2: 45421
A3: ITEMS | B3: RETAIL PRICE | C3: PCS SOLD | D3: SALES | E3: DISCOUNTED PRICE | F3: PCS SOLD | G3: SALES | H3: SPECIAL DISC. PRICE | I3: PCS SOLD | J3: SALES | K3: TOTAL SALES | L3: TOTALQTY SOLD | M3: PRODUCTION PRICE | N3: 12% Vat | O3: 10% Mark Up | P3: PROFIT
A4: NAPOLIZ
A5: Backpack Bag | B5: 1750 | D5: =B5*C5 -> 0 | E5: 1600 | G5: =E5*F5 -> 0 | H5: 1400 | J5: =H5*I5 -> 0 | K5: =D5+G5+J5 -> 0 | L5: =C5+F5+I5 -> 0 | M5: 840 | N5: 100.8 | O5: 84 | P5: =((B5-M5)*C5)+((E5-M5)*F5)+((H5-M5)*I5) -> 0
A6: Black Tote Bag (Phased Out) | B6: 280 | D6: =B6*C6 -> 0 | G6: =E6*F6 -> 0 | J6: =H6*I6 -> 0 | K6: =D6+G6+J6 -> 0 | L6: =C6+F6+I6 -> 0 | M6: 230 | P6: =((B6-M6)*C6)+((E6-M6)*F6)+((H6-M6)*I6) -> 0
A7: Double Canopy | B7: 639 | D7: =B7*C7 -> 0 | E7: 575 | G7: =E7*F7 -> 0 | H7: 500 | J7: =H7*I7 -> 0 | K7: =D7+G7+J7 -> 0 | L7: =C7+F7+I7 -> 0 | M7: 330 | N7: 39.6 | O7: 33 | P7: =((B7-M7)*C7)+((E7-M7)*F7)+((H7-M7)*I7) -> 0
A8: Laptop Bag | B8: 1450 | D8: =B8*C8 -> 0 | E8: 1400 | G8: =E8*F8 -> 0 | H8: 1250 | J8: =H8*I8 -> 0 | K8: =D8+G8+J8 -> 0 | L8: =C8+F8+I8 -> 0 | M8: 840 | N8: 100.8 | O8: 84 | P8: =((B8-M8)*C8)+((E8-M8)*F8)+((H8-M8)*I8) -> 0
A9: Script Santo Tomas with Tiger Back (B) | B9: 480 | C9: 3 | D9: =B9*C9 -> 1440 | E9: 460 | G9: =E9*F9 -> 0 | H9: 450 | I9: 1 | J9: =H9*I9 -> 450 | K9: =D9+G9+J9 -> 1890 | L9: =C9+F9+I9 -> 4 | M9: 360 | N9: 43.2 | O9: 36 | P9: =((B9-M9)*C9)+((E9-M9)*F9)+((H9-M9)*I9) -> 450
A10: Side Tiger Hoodie | B10: 1480 | D10: =B10*C10 -> 0 | E10: 1400 | G10: =E10*F10 -> 0 | H10: 1375 | J10: =H10*I10 -> 0 | K10: =D10+G10+J10 -> 0 | L10: =C10+F10+I10 -> 0 | M10: 1125 | N10: 135 | O10: 112.5 | P10: =((B10-M10)*C10)+((E10-M10)*F10)+((H10-M10)*I10) -> 0
A11: Sling Bag | B11: 330 | D11: =B11*C11 -> 0 | E11: 320 | G11: =E11*F11 -> 0 | H11: 300 | J11: =H11*I11 -> 0 | K11: =D11+G11+J11 -> 0 | L11: =C11+F11+I11 -> 0 | M11: 260 | N11: 31.2 | O11: 26 | P11: =((B11-M11)*C11)+((E11-M11)*F11)+((H11-M11)*I11) -> 0
A12: Front Tiger Hoodie | B12: 1440 | C12: 1 | D12: =B12*C12 -> 1440 | E12: 1400 | G12: =E12*F12 -> 0 | H12: 1375 | J12: =H12*I12 -> 0 | K12: =D12+G12+J12 -> 1440 | L12: =C12+F12+I12 -> 1 | M12: 1125 | N12: 135 | O12: 112.5 | P12: =((B12-M12)*C12)+((E12-M12)*F12)+((H12-M12)*I12) -> 315
A13: University of Santo Tomas (B) | B13: 450 | C13: 6 | D13: =B13*C13 -> 2700 | E13: 440 | G13: =E13*F13 -> 0 | H13: 425 | J13: =H13*I13 -> 0 | K13: =D13+G13+J13 -> 2700 | L13: =C13+F13+I13 -> 6 | M13: 360 | N13: 43.2 | O13: 36 | P13: =((B13-M13)*C13)+((E13-M13)*F13)+((H13-M13)*I13) -> 540
A14: UST Tiger Front and Back Graphic (W) | B14: 500 | C14: 7 | D14: =B14*C14 -> 3500 | E14: 480 | G14: =E14*F14 -> 0 | H14: 450 | J14: =H14*I14 -> 0 | K14: =D14+G14+J14 -> 3500 | L14: =C14+F14+I14 -> 7 | M14: 360 | N14: 43.2 | O14: 36 | P14: =((B14-M14)*C14)+((E14-M14)*F14)+((H14-M14)*I14) -> 980
A15: White Tote Bag | B15: 260 | D15: =B15*C15 -> 0 | E15: 250 | G15: =E15*F15 -> 0 | H15: 240 | J15: =H15*I15 -> 0 | K15: =D15+G15+J15 -> 0 | L15: =C15+F15+I15 -> 0 | M15: 200 | N15: 24 | O15: 20 | P15: =((B15-M15)*C15)+((E15-M15)*F15)+((H15-M15)*I15) -> 0
A16: Wind Breaker | B16: 1650 | C16: 1 | D16: =B16*C16 -> 1650 | E16: 1600 | G16: =E16*F16 -> 0 | H16: 1500 | J16: =H16*I16 -> 0 | K16: =D16+G16+J16 -> 1650 | L16: =C16+F16+I16 -> 1 | M16: 1125 | N16: 135 | O16: 112.5 | P16: =((B16-M16)*C16)+((E16-M16)*F16)+((H16-M16)*I16) -> 525
C17: TOTAL | D17: =SUM(D5:D16) -> 10730 | F17: TOTAL | G17: =SUM(G5:G16) -> 0 | I17: TOTAL | J17: =SUM(J5:J16) -> 450 | K17: =D17+G17+J17 -> 11180 | M17: TOTAL | P17: =SUM(P5:P16) -> 2810
A18: JYL | B18: RETAIL PRICE | C18: PCS SOLD | D18: SALES | E18: DISCOUNTED PRICE | F18: PCS SOLD | G18: SALES | H18: SPECIAL DISC. PRICE | I18: PCS SOLD | J18: SALES | K18: TOTAL SALES | L18: TOTALQTY SOLD | M18: PRODUCTION PRICE | N18: 12% Vat | O18: 10% Mark Up | P18: PROFIT
A19: GT Shirt | B19: 375 | D19: =B19*C19 -> 0 | E19: 350 | G19: =E19*F19 -> 0 | H19: 325 | J19: =H19*I19 -> 0 | K19: =D19+G19+J19 -> 0 | L19: =C19+F19+I19 -> 0 | M19: 250 | N19: 30 | O19: 25 | P19: =((B19-M19)*C19)+((E19-M19)*F19)+((H19-M19)*I19) -> 0
A20: Jacket | B20: 1900 | C20: 4 | D20: =B20*C20 -> 7600 | E20: 1700 | G20: =E20*F20 -> 0 | H20: 1500 | J20: =H20*I20 -> 0 | K20: =D20+G20+J20 -> 7600 | L20: =C20+F20+I20 -> 4 | M20: 1200 | N20: 144 | O20: 120 | P20: =((B20-M20)*C20)+((E20-M20)*F20)+((H20-M20)*I20) -> 2800
A21: Poloshirt 123456 | B21: 860 | C21: 1 | D21: =B21*C21 -> 860 | E21: 800 | G21: =E21*F21 -> 0 | H21: 750 | J21: =H21*I21 -> 0 | K21: =D21+G21+J21 -> 860 | L21: =C21+F21+I21 -> 1 | M21: 600 | N21: 72 | O21: 60 | P21: =((B21-M21)*C21)+((E21-M21)*F21)+((H21-M21)*I21) -> 260
